package perevodchik.world.structure;

import net.minecraft.util.math.BlockPos;
import net.minecraft.world.World;
import net.minecraft.world.gen.feature.WorldGenerator;

import java.util.Random;

public class StructureMonsterTower11 extends WorldGenerator
{
	/*protected Block[] GetValidSpawnBlocks()
	{
		return new Block[]
		{
			Blocks.grass,
			Blocks.stone,
			Blocks.dirt,
			Blocks.cobblestone,
			Blocks.planks,
			Blocks.gravel,
		};
	}

	public boolean LocationIsValidSpawn(World world, int x, int y, int z)
	{
		int distanceToAir = 0;
		Block checkBlock = world.getBlock(x, y, z);

		while (checkBlock != Blocks.air)
		{
			distanceToAir++;
			checkBlock = world.getBlock(x, y + distanceToAir, z);
		}

		if (distanceToAir > 1)
		{
			return false;
		}

		y += distanceToAir - 1;

		Block block = world.getBlock(x, y, z);
		Block blockAbove = world.getBlock(x, y + 1, z);
		Block blockBelow = world.getBlock(x, y - 1, z);

		for (Block i : GetValidSpawnBlocks())
		{
			if (blockAbove != Blocks.air)
			{
				return false;
			}
			if (block == i)
			{
				return true;
			}
			else if (block == Blocks.snow_layer && blockBelow == i)
			else if (block.getMaterial() == Material.plants && blockBelow == i)
			{
				return true;
			}
		}
		return false;
	}
*/
	/*public boolean generate(World world, Random rand, int x, int y, int z)
	{
		if(!LocationIsValidSpawn(world, x + 6, y, z + 6))
		{
			return false;
		}

		world.setBlock(x + 0, y + 0, z + 0, Blocks.grass, 0, 3);
		world.setBlock(x + 1, y + 0, z + 0, Blocks.grass, 0, 3);
		world.setBlock(x + 2, y + 0, z + 0, Blocks.grass, 0, 3);
		world.setBlock(x + 3, y + 0, z + 0, Blocks.grass, 0, 3);
		world.setBlock(x + 4, y + 0, z + 0, Blocks.grass, 0, 3);
		world.setBlock(x + 5, y + 0, z + 0, Blocks.cobblestone, 0, 3);
		world.setBlock(x + 6, y + 0, z + 0, Blocks.cobblestone, 0, 3);
		world.setBlock(x + 7, y + 0, z + 0, Blocks.cobblestone, 0, 3);
		world.setBlock(x + 8, y + 0, z + 0, Blocks.grass, 0, 3);
		world.setBlock(x + 9, y + 0, z + 0, Blocks.grass, 0, 3);
		world.setBlock(x + 10, y + 0, z + 0, Blocks.grass, 0, 3);
		world.setBlock(x + 11, y + 0, z + 0, Blocks.grass, 0, 3);
		world.setBlock(x + 12, y + 0, z + 0, Blocks.grass, 0, 3);
		world.setBlock(x + 0, y + 0, z + 1, Blocks.grass, 0, 3);
		world.setBlock(x + 1, y + 0, z + 1, Blocks.grass, 0, 3);
		world.setBlock(x + 2, y + 0, z + 1, Blocks.grass, 0, 3);
		world.setBlock(x + 3, y + 0, z + 1, Blocks.grass, 0, 3);
		world.setBlock(x + 4, y + 0, z + 1, Blocks.grass, 0, 3);
		world.setBlock(x + 5, y + 0, z + 1, Blocks.cobblestone, 0, 3);
		world.setBlock(x + 6, y + 0, z + 1, Blocks.cobblestone, 0, 3);
		world.setBlock(x + 7, y + 0, z + 1, Blocks.cobblestone, 0, 3);
		world.setBlock(x + 8, y + 0, z + 1, Blocks.grass, 0, 3);
		world.setBlock(x + 9, y + 0, z + 1, Blocks.grass, 0, 3);
		world.setBlock(x + 10, y + 0, z + 1, Blocks.grass, 0, 3);
		world.setBlock(x + 11, y + 0, z + 1, Blocks.grass, 0, 3);
		world.setBlock(x + 12, y + 0, z + 1, Blocks.grass, 0, 3);
		world.setBlock(x + 0, y + 0, z + 2, Blocks.grass, 0, 3);
		world.setBlock(x + 1, y + 0, z + 2, Blocks.grass, 0, 3);
		world.setBlock(x + 2, y + 0, z + 2, Blocks.grass, 0, 3);
		world.setBlock(x + 3, y + 0, z + 2, Blocks.dirt, 0, 3);
		world.setBlock(x + 4, y + 0, z + 2, Blocks.dirt, 0, 3);
		world.setBlock(x + 5, y + 0, z + 2, Blocks.cobblestone, 0, 3);
		world.setBlock(x + 6, y + 0, z + 2, Blocks.cobblestone, 0, 3);
		world.setBlock(x + 7, y + 0, z + 2, Blocks.cobblestone, 0, 3);
		world.setBlock(x + 8, y + 0, z + 2, Blocks.dirt, 0, 3);
		world.setBlock(x + 9, y + 0, z + 2, Blocks.dirt, 0, 3);
		world.setBlock(x + 10, y + 0, z + 2, Blocks.grass, 0, 3);
		world.setBlock(x + 11, y + 0, z + 2, Blocks.grass, 0, 3);
		world.setBlock(x + 12, y + 0, z + 2, Blocks.grass, 0, 3);
		world.setBlock(x + 0, y + 0, z + 3, Blocks.grass, 0, 3);
		world.setBlock(x + 1, y + 0, z + 3, Blocks.grass, 0, 3);
		world.setBlock(x + 2, y + 0, z + 3, Blocks.dirt, 0, 3);
		world.setBlock(x + 3, y + 0, z + 3, Blocks.cobblestone, 0, 3);
		world.setBlock(x + 4, y + 0, z + 3, Blocks.cobblestone, 0, 3);
		world.setBlock(x + 5, y + 0, z + 3, Blocks.dirt, 0, 3);
		world.setBlock(x + 6, y + 0, z + 3, Blocks.cobblestone, 0, 3);
		world.setBlock(x + 7, y + 0, z + 3, Blocks.dirt, 0, 3);
		world.setBlock(x + 8, y + 0, z + 3, Blocks.cobblestone, 0, 3);
		world.setBlock(x + 9, y + 0, z + 3, Blocks.cobblestone, 0, 3);
		world.setBlock(x + 10, y + 0, z + 3, Blocks.dirt, 0, 3);
		world.setBlock(x + 11, y + 0, z + 3, Blocks.grass, 0, 3);
		world.setBlock(x + 12, y + 0, z + 3, Blocks.grass, 0, 3);
		world.setBlock(x + 0, y + 0, z + 4, Blocks.grass, 0, 3);
		world.setBlock(x + 1, y + 0, z + 4, Blocks.grass, 0, 3);
		world.setBlock(x + 2, y + 0, z + 4, Blocks.dirt, 0, 3);
		world.setBlock(x + 3, y + 0, z + 4, Blocks.cobblestone, 0, 3);
		world.setBlock(x + 4, y + 0, z + 4, Blocks.cobblestone, 0, 3);
		world.setBlock(x + 5, y + 0, z + 4, Blocks.cobblestone, 0, 3);
		world.setBlock(x + 6, y + 0, z + 4, Blocks.cobblestone, 0, 3);
		world.setBlock(x + 7, y + 0, z + 4, Blocks.cobblestone, 0, 3);
		world.setBlock(x + 8, y + 0, z + 4, Blocks.cobblestone, 0, 3);
		world.setBlock(x + 9, y + 0, z + 4, Blocks.cobblestone, 0, 3);
		world.setBlock(x + 10, y + 0, z + 4, Blocks.dirt, 0, 3);
		world.setBlock(x + 11, y + 0, z + 4, Blocks.grass, 0, 3);
		world.setBlock(x + 12, y + 0, z + 4, Blocks.grass, 0, 3);
		world.setBlock(x + 0, y + 0, z + 5, Blocks.dirt, 0, 3);
		world.setBlock(x + 1, y + 0, z + 5, Blocks.dirt, 0, 3);
		world.setBlock(x + 2, y + 0, z + 5, Blocks.dirt, 0, 3);
		world.setBlock(x + 3, y + 0, z + 5, Blocks.cobblestone, 0, 3);
		world.setBlock(x + 4, y + 0, z + 5, Blocks.cobblestone, 0, 3);
		world.setBlock(x + 5, y + 0, z + 5, Blocks.cobblestone, 0, 3);
		world.setBlock(x + 6, y + 0, z + 5, Blocks.cobblestone, 0, 3);
		world.setBlock(x + 7, y + 0, z + 5, Blocks.cobblestone, 0, 3);
		world.setBlock(x + 8, y + 0, z + 5, Blocks.cobblestone, 0, 3);
		world.setBlock(x + 9, y + 0, z + 5, Blocks.cobblestone, 0, 3);
		world.setBlock(x + 10, y + 0, z + 5, Blocks.dirt, 0, 3);
		world.setBlock(x + 11, y + 0, z + 5, Blocks.dirt, 0, 3);
		world.setBlock(x + 12, y + 0, z + 5, Blocks.dirt, 0, 3);
		world.setBlock(x + 0, y + 0, z + 6, Blocks.grass, 0, 3);
		world.setBlock(x + 1, y + 0, z + 6, Blocks.grass, 0, 3);
		world.setBlock(x + 2, y + 0, z + 6, Blocks.grass, 0, 3);
		world.setBlock(x + 3, y + 0, z + 6, Blocks.dirt, 0, 3);
		world.setBlock(x + 4, y + 0, z + 6, Blocks.cobblestone, 0, 3);
		world.setBlock(x + 5, y + 0, z + 6, Blocks.cobblestone, 0, 3);
		world.setBlock(x + 6, y + 0, z + 6, Blocks.cobblestone, 0, 3);
		world.setBlock(x + 7, y + 0, z + 6, Blocks.cobblestone, 0, 3);
		world.setBlock(x + 8, y + 0, z + 6, Blocks.cobblestone, 0, 3);
		world.setBlock(x + 9, y + 0, z + 6, Blocks.dirt, 0, 3);
		world.setBlock(x + 10, y + 0, z + 6, Blocks.grass, 0, 3);
		world.setBlock(x + 11, y + 0, z + 6, Blocks.grass, 0, 3);
		world.setBlock(x + 12, y + 0, z + 6, Blocks.grass, 0, 3);
		world.setBlock(x + 0, y + 0, z + 7, Blocks.grass, 0, 3);
		world.setBlock(x + 1, y + 0, z + 7, Blocks.grass, 0, 3);
		world.setBlock(x + 2, y + 0, z + 7, Blocks.grass, 0, 3);
		world.setBlock(x + 3, y + 0, z + 7, Blocks.dirt, 0, 3);
		world.setBlock(x + 4, y + 0, z + 7, Blocks.cobblestone, 0, 3);
		world.setBlock(x + 5, y + 0, z + 7, Blocks.cobblestone, 0, 3);
		world.setBlock(x + 6, y + 0, z + 7, Blocks.cobblestone, 0, 3);
		world.setBlock(x + 7, y + 0, z + 7, Blocks.cobblestone, 0, 3);
		world.setBlock(x + 8, y + 0, z + 7, Blocks.cobblestone, 0, 3);
		world.setBlock(x + 9, y + 0, z + 7, Blocks.dirt, 0, 3);
		world.setBlock(x + 10, y + 0, z + 7, Blocks.grass, 0, 3);
		world.setBlock(x + 11, y + 0, z + 7, Blocks.grass, 0, 3);
		world.setBlock(x + 12, y + 0, z + 7, Blocks.grass, 0, 3);
		world.setBlock(x + 0, y + 0, z + 8, Blocks.grass, 0, 3);
		world.setBlock(x + 1, y + 0, z + 8, Blocks.grass, 0, 3);
		world.setBlock(x + 2, y + 0, z + 8, Blocks.grass, 0, 3);
		world.setBlock(x + 3, y + 0, z + 8, Blocks.dirt, 0, 3);
		world.setBlock(x + 4, y + 0, z + 8, Blocks.cobblestone, 0, 3);
		world.setBlock(x + 5, y + 0, z + 8, Blocks.cobblestone, 0, 3);
		world.setBlock(x + 6, y + 0, z + 8, Blocks.cobblestone, 0, 3);
		world.setBlock(x + 7, y + 0, z + 8, Blocks.cobblestone, 0, 3);
		world.setBlock(x + 8, y + 0, z + 8, Blocks.cobblestone, 0, 3);
		world.setBlock(x + 9, y + 0, z + 8, Blocks.dirt, 0, 3);
		world.setBlock(x + 10, y + 0, z + 8, Blocks.grass, 0, 3);
		world.setBlock(x + 11, y + 0, z + 8, Blocks.grass, 0, 3);
		world.setBlock(x + 12, y + 0, z + 8, Blocks.grass, 0, 3);
		world.setBlock(x + 0, y + 0, z + 9, Blocks.grass, 0, 3);
		world.setBlock(x + 1, y + 0, z + 9, Blocks.grass, 0, 3);
		world.setBlock(x + 2, y + 0, z + 9, Blocks.grass, 0, 3);
		world.setBlock(x + 3, y + 0, z + 9, Blocks.dirt, 0, 3);
		world.setBlock(x + 4, y + 0, z + 9, Blocks.cobblestone, 0, 3);
		world.setBlock(x + 5, y + 0, z + 9, Blocks.cobblestone, 0, 3);
		world.setBlock(x + 6, y + 0, z + 9, Blocks.cobblestone, 0, 3);
		world.setBlock(x + 7, y + 0, z + 9, Blocks.cobblestone, 0, 3);
		world.setBlock(x + 8, y + 0, z + 9, Blocks.cobblestone, 0, 3);
		world.setBlock(x + 9, y + 0, z + 9, Blocks.dirt, 0, 3);
		world.setBlock(x + 10, y + 0, z + 9, Blocks.grass, 0, 3);
		world.setBlock(x + 11, y + 0, z + 9, Blocks.grass, 0, 3);
		world.setBlock(x + 12, y + 0, z + 9, Blocks.grass, 0, 3);
		world.setBlock(x + 0, y + 0, z + 10, Blocks.grass, 0, 3);
		world.setBlock(x + 1, y + 0, z + 10, Blocks.grass, 0, 3);
		world.setBlock(x + 2, y + 0, z + 10, Blocks.grass, 0, 3);
		world.setBlock(x + 3, y + 0, z + 10, Blocks.dirt, 0, 3);
		world.setBlock(x + 4, y + 0, z + 10, Blocks.dirt, 0, 3);
		world.setBlock(x + 5, y + 0, z + 10, Blocks.dirt, 0, 3);
		world.setBlock(x + 6, y + 0, z + 10, Blocks.dirt, 0, 3);
		world.setBlock(x + 7, y + 0, z + 10, Blocks.dirt, 0, 3);
		world.setBlock(x + 8, y + 0, z + 10, Blocks.dirt, 0, 3);
		world.setBlock(x + 9, y + 0, z + 10, Blocks.dirt, 0, 3);
		world.setBlock(x + 10, y + 0, z + 10, Blocks.grass, 0, 3);
		world.setBlock(x + 11, y + 0, z + 10, Blocks.grass, 0, 3);
		world.setBlock(x + 12, y + 0, z + 10, Blocks.grass, 0, 3);
		world.setBlock(x + 0, y + 0, z + 11, Blocks.dirt, 0, 3);
		world.setBlock(x + 1, y + 0, z + 11, Blocks.dirt, 0, 3);
		world.setBlock(x + 2, y + 0, z + 11, Blocks.dirt, 0, 3);
		world.setBlock(x + 3, y + 0, z + 11, Blocks.grass, 0, 3);
		world.setBlock(x + 4, y + 0, z + 11, Blocks.grass, 0, 3);
		world.setBlock(x + 5, y + 0, z + 11, Blocks.grass, 0, 3);
		world.setBlock(x + 6, y + 0, z + 11, Blocks.grass, 0, 3);
		world.setBlock(x + 7, y + 0, z + 11, Blocks.grass, 0, 3);
		world.setBlock(x + 8, y + 0, z + 11, Blocks.grass, 0, 3);
		world.setBlock(x + 9, y + 0, z + 11, Blocks.grass, 0, 3);
		world.setBlock(x + 10, y + 0, z + 11, Blocks.dirt, 0, 3);
		world.setBlock(x + 11, y + 0, z + 11, Blocks.dirt, 0, 3);
		world.setBlock(x + 12, y + 0, z + 11, Blocks.dirt, 0, 3);
		world.setBlock(x + 0, y + 0, z + 12, Blocks.grass, 0, 3);
		world.setBlock(x + 1, y + 0, z + 12, Blocks.grass, 0, 3);
		world.setBlock(x + 2, y + 0, z + 12, Blocks.dirt, 0, 3);
		world.setBlock(x + 3, y + 0, z + 12, Blocks.grass, 0, 3);
		world.setBlock(x + 4, y + 0, z + 12, Blocks.grass, 0, 3);
		world.setBlock(x + 5, y + 0, z + 12, Blocks.grass, 0, 3);
		world.setBlock(x + 6, y + 0, z + 12, Blocks.grass, 0, 3);
		world.setBlock(x + 7, y + 0, z + 12, Blocks.grass, 0, 3);
		world.setBlock(x + 8, y + 0, z + 12, Blocks.grass, 0, 3);
		world.setBlock(x + 9, y + 0, z + 12, Blocks.grass, 0, 3);
		world.setBlock(x + 10, y + 0, z + 12, Blocks.dirt, 0, 3);
		world.setBlock(x + 11, y + 0, z + 12, Blocks.grass, 0, 3);
		world.setBlock(x + 12, y + 0, z + 12, Blocks.grass, 0, 3);
		world.setBlock(x + 3, y + 1, z + 1, Blocks.leaves, 5, 3);
		world.setBlock(x + 4, y + 1, z + 1, Blocks.leaves, 5, 3);
		world.setBlock(x + 3, y + 1, z + 2, Blocks.stonebrick, 0, 3);
		world.setBlock(x + 4, y + 1, z + 2, Blocks.stone, 0, 3);
		world.setBlock(x + 8, y + 1, z + 2, Blocks.stonebrick, 0, 3);
		world.setBlock(x + 9, y + 1, z + 2, Blocks.stonebrick, 0, 3);
		world.setBlock(x + 2, y + 1, z + 3, Blocks.stonebrick, 1, 3);
		world.setBlock(x + 5, y + 1, z + 3, Blocks.stone, 0, 3);
		world.setBlock(x + 7, y + 1, z + 3, Blocks.stonebrick, 0, 3);
		world.setBlock(x + 10, y + 1, z + 3, Blocks.stonebrick, 0, 3);
		world.setBlock(x + 11, y + 1, z + 3, Blocks.leaves, 5, 3);
		world.setBlock(x + 1, y + 1, z + 4, Blocks.leaves, 5, 3);
		world.setBlock(x + 2, y + 1, z + 4, Blocks.stone, 0, 3);
		world.setBlock(x + 10, y + 1, z + 4, Blocks.stone, 0, 3);
		world.setBlock(x + 11, y + 1, z + 4, Blocks.leaves, 5, 3);
		world.setBlock(x + 12, y + 1, z + 4, Blocks.leaves, 5, 3);
		world.setBlock(x + 0, y + 1, z + 5, Blocks.stonebrick, 1, 3);
		world.setBlock(x + 1, y + 1, z + 5, Blocks.stone, 0, 3);
		world.setBlock(x + 2, y + 1, z + 5, Blocks.stonebrick, 1, 3);
		world.setBlock(x + 10, y + 1, z + 5, Blocks.stonebrick, 1, 3);
		world.setBlock(x + 11, y + 1, z + 5, Blocks.stone, 0, 3);
		world.setBlock(x + 12, y + 1, z + 5, Blocks.stonebrick, 1, 3);
		world.setBlock(x + 0, y + 1, z + 6, Blocks.leaves, 5, 3);
		world.setBlock(x + 1, y + 1, z + 6, Blocks.leaves, 5, 3);
		world.setBlock(x + 2, y + 1, z + 6, Blocks.leaves, 5, 3);
		world.setBlock(x + 3, y + 1, z + 6, Blocks.stonebrick, 0, 3);
		world.setBlock(x + 9, y + 1, z + 6, Blocks.stonebrick, 0, 3);
		world.setBlock(x + 10, y + 1, z + 6, Blocks.leaves, 5, 3);
		world.setBlock(x + 11, y + 1, z + 6, Blocks.leaves, 5, 3);
		world.setBlock(x + 3, y + 1, z + 7, Blocks.stonebrick, 1, 3);
		world.setBlock(x + 9, y + 1, z + 7, Blocks.stonebrick, 0, 3);
		world.setBlock(x + 10, y + 1, z + 7, Blocks.leaves, 5, 3);
		world.setBlock(x + 11, y + 1, z + 7, Blocks.leaves, 13, 3);
		world.setBlock(x + 2, y + 1, z + 8, Blocks.leaves, 5, 3);
		world.setBlock(x + 3, y + 1, z + 8, Blocks.stone, 0, 3);
		world.setBlock(x + 9, y + 1, z + 8, Blocks.stone, 0, 3);
		world.setBlock(x + 10, y + 1, z + 8, Blocks.leaves, 5, 3);
		world.setBlock(x + 3, y + 1, z + 9, Blocks.stonebrick, 0, 3);
		world.setBlock(x + 9, y + 1, z + 9, Blocks.stonebrick, 1, 3);
		world.setBlock(x + 10, y + 1, z + 9, Blocks.leaves, 5, 3);
		world.setBlock(x + 0, y + 1, z + 10, Blocks.leaves, 13, 3);
		world.setBlock(x + 1, y + 1, z + 10, Blocks.leaves, 13, 3);
		world.setBlock(x + 3, y + 1, z + 10, Blocks.stonebrick, 0, 3);
		world.setBlock(x + 4, y + 1, z + 10, Blocks.stonebrick, 1, 3);
		world.setBlock(x + 5, y + 1, z + 10, Blocks.stone, 0, 3);
		world.setBlock(x + 6, y + 1, z + 10, Blocks.stone, 0, 3);
		world.setBlock(x + 7, y + 1, z + 10, Blocks.stone, 0, 3);
		world.setBlock(x + 8, y + 1, z + 10, Blocks.stone, 0, 3);
		world.setBlock(x + 9, y + 1, z + 10, Blocks.stonebrick, 1, 3);
		world.setBlock(x + 10, y + 1, z + 10, Blocks.leaves, 5, 3);
		world.setBlock(x + 11, y + 1, z + 10, Blocks.leaves, 5, 3);
		world.setBlock(x + 12, y + 1, z + 10, Blocks.leaves, 5, 3);
		world.setBlock(x + 0, y + 1, z + 11, Blocks.stonebrick, 1, 3);
		world.setBlock(x + 1, y + 1, z + 11, Blocks.stonebrick, 0, 3);
		world.setBlock(x + 2, y + 1, z + 11, Blocks.stone, 0, 3);
		world.setBlock(x + 3, y + 1, z + 11, Blocks.leaves, 13, 3);
		world.setBlock(x + 5, y + 1, z + 11, Blocks.leaves, 5, 3);
		world.setBlock(x + 6, y + 1, z + 11, Blocks.leaves, 5, 3);
		world.setBlock(x + 7, y + 1, z + 11, Blocks.leaves, 5, 3);
		world.setBlock(x + 10, y + 1, z + 11, Blocks.stonebrick, 1, 3);
		world.setBlock(x + 11, y + 1, z + 11, Blocks.stone, 0, 3);
		world.setBlock(x + 12, y + 1, z + 11, Blocks.stone, 0, 3);
		world.setBlock(x + 2, y + 1, z + 12, Blocks.stonebrick, 1, 3);
		world.setBlock(x + 3, y + 1, z + 12, Blocks.leaves, 13, 3);
		world.setBlock(x + 10, y + 1, z + 12, Blocks.stonebrick, 1, 3);
		world.setBlock(x + 11, y + 1, z + 12, Blocks.leaves, 5, 3);
		world.setBlock(x + 12, y + 1, z + 12, Blocks.leaves, 5, 3);
		world.setBlock(x + 3, y + 2, z + 1, Blocks.leaves, 5, 3);
		world.setBlock(x + 3, y + 2, z + 2, Blocks.stonebrick, 1, 3);
		world.setBlock(x + 4, y + 2, z + 2, Blocks.stonebrick, 0, 3);
		world.setBlock(x + 8, y + 2, z + 2, Blocks.stone, 0, 3);
		world.setBlock(x + 9, y + 2, z + 2, Blocks.stone, 0, 3);
		world.setBlock(x + 2, y + 2, z + 3, Blocks.stonebrick, 1, 3);
		world.setBlock(x + 5, y + 2, z + 3, Blocks.stonebrick, 0, 3);
		world.setBlock(x + 7, y + 2, z + 3, Blocks.stonebrick, 1, 3);
		world.setBlock(x + 10, y + 2, z + 3, Blocks.stone, 0, 3);
		world.setBlock(x + 1, y + 2, z + 4, Blocks.leaves, 5, 3);
		world.setBlock(x + 2, y + 2, z + 4, Blocks.stonebrick, 1, 3);
		world.setBlock(x + 10, y + 2, z + 4, Blocks.stonebrick, 0, 3);
		world.setBlock(x + 11, y + 2, z + 4, Blocks.leaves, 5, 3);
		world.setBlock(x + 0, y + 2, z + 5, Blocks.stonebrick, 1, 3);
		world.setBlock(x + 1, y + 2, z + 5, Blocks.stone, 0, 3);
		world.setBlock(x + 2, y + 2, z + 5, Blocks.stonebrick, 0, 3);
		world.setBlock(x + 10, y + 2, z + 5, Blocks.stonebrick, 1, 3);
		world.setBlock(x + 11, y + 2, z + 5, Blocks.stone, 0, 3);
		world.setBlock(x + 12, y + 2, z + 5, Blocks.stone, 0, 3);
		world.setBlock(x + 1, y + 2, z + 6, Blocks.leaves, 5, 3);
		world.setBlock(x + 3, y + 2, z + 6, Blocks.stonebrick, 1, 3);
		world.setBlock(x + 9, y + 2, z + 6, Blocks.stonebrick, 1, 3);
		world.setBlock(x + 10, y + 2, z + 6, Blocks.leaves, 13, 3);
		world.setBlock(x + 11, y + 2, z + 6, Blocks.leaves, 13, 3);
		world.setBlock(x + 2, y + 2, z + 7, Blocks.leaves, 5, 3);
		world.setBlock(x + 3, y + 2, z + 7, Blocks.stonebrick, 0, 3);
		world.setBlock(x + 9, y + 2, z + 7, Blocks.stonebrick, 0, 3);
		world.setBlock(x + 2, y + 2, z + 8, Blocks.leaves, 5, 3);
		world.setBlock(x + 3, y + 2, z + 8, Blocks.stone, 0, 3);
		world.setBlock(x + 9, y + 2, z + 8, Blocks.stonebrick, 0, 3);
		world.setBlock(x + 2, y + 2, z + 9, Blocks.leaves, 5, 3);
		world.setBlock(x + 3, y + 2, z + 9, Blocks.stone, 0, 3);
		world.setBlock(x + 9, y + 2, z + 9, Blocks.stone, 0, 3);
		world.setBlock(x + 10, y + 2, z + 9, Blocks.leaves, 5, 3);
		world.setBlock(x + 0, y + 2, z + 10, Blocks.leaves, 13, 3);
		world.setBlock(x + 2, y + 2, z + 10, Blocks.leaves, 5, 3);
		world.setBlock(x + 3, y + 2, z + 10, Blocks.stonebrick, 0, 3);
		world.setBlock(x + 4, y + 2, z + 10, Blocks.stone, 0, 3);
		world.setBlock(x + 5, y + 2, z + 10, Blocks.stonebrick, 0, 3);
		world.setBlock(x + 6, y + 2, z + 10, Blocks.stone, 0, 3);
		world.setBlock(x + 7, y + 2, z + 10, Blocks.stonebrick, 0, 3);
		world.setBlock(x + 8, y + 2, z + 10, Blocks.stonebrick, 0, 3);
		world.setBlock(x + 9, y + 2, z + 10, Blocks.stonebrick, 1, 3);
		world.setBlock(x + 10, y + 2, z + 10, Blocks.leaves, 5, 3);
		world.setBlock(x + 11, y + 2, z + 10, Blocks.leaves, 5, 3);
		world.setBlock(x + 0, y + 2, z + 11, Blocks.stone, 0, 3);
		world.setBlock(x + 1, y + 2, z + 11, Blocks.stone, 0, 3);
		world.setBlock(x + 2, y + 2, z + 11, Blocks.stonebrick, 0, 3);
		world.setBlock(x + 3, y + 2, z + 11, Blocks.leaves, 13, 3);
		world.setBlock(x + 4, y + 2, z + 11, Blocks.leaves, 5, 3);
		world.setBlock(x + 5, y + 2, z + 11, Blocks.leaves, 5, 3);
		world.setBlock(x + 6, y + 2, z + 11, Blocks.leaves, 5, 3);
		world.setBlock(x + 10, y + 2, z + 11, Blocks.stonebrick, 0, 3);
		world.setBlock(x + 11, y + 2, z + 11, Blocks.stonebrick, 0, 3);
		world.setBlock(x + 12, y + 2, z + 11, Blocks.stonebrick, 0, 3);
		world.setBlock(x + 2, y + 2, z + 12, Blocks.stonebrick, 0, 3);
		world.setBlock(x + 10, y + 2, z + 12, Blocks.stonebrick, 0, 3);
		world.setBlock(x + 11, y + 2, z + 12, Blocks.leaves, 5, 3);
		world.setBlock(x + 3, y + 3, z + 2, Blocks.stone, 0, 3);
		world.setBlock(x + 4, y + 3, z + 2, Blocks.stone, 0, 3);
		world.setBlock(x + 8, y + 3, z + 2, Blocks.stonebrick, 1, 3);
		world.setBlock(x + 9, y + 3, z + 2, Blocks.stonebrick, 0, 3);
		world.setBlock(x + 2, y + 3, z + 3, Blocks.stone, 0, 3);
		world.setBlock(x + 5, y + 3, z + 3, Blocks.stonebrick, 0, 3);
		world.setBlock(x + 6, y + 3, z + 3, Blocks.stonebrick, 0, 3);
		world.setBlock(x + 7, y + 3, z + 3, Blocks.stonebrick, 1, 3);
		world.setBlock(x + 10, y + 3, z + 3, Blocks.stone, 0, 3);
		world.setBlock(x + 1, y + 3, z + 4, Blocks.leaves, 5, 3);
		world.setBlock(x + 2, y + 3, z + 4, Blocks.stonebrick, 1, 3);
		world.setBlock(x + 10, y + 3, z + 4, Blocks.stonebrick, 1, 3);
		world.setBlock(x + 0, y + 3, z + 5, Blocks.stone, 0, 3);
		world.setBlock(x + 1, y + 3, z + 5, Blocks.stonebrick, 1, 3);
		world.setBlock(x + 2, y + 3, z + 5, Blocks.stonebrick, 0, 3);
		world.setBlock(x + 10, y + 3, z + 5, Blocks.stone, 0, 3);
		world.setBlock(x + 11, y + 3, z + 5, Blocks.stonebrick, 0, 3);
		world.setBlock(x + 12, y + 3, z + 5, Blocks.stonebrick, 1, 3);
		world.setBlock(x + 1, y + 3, z + 6, Blocks.leaves, 5, 3);
		world.setBlock(x + 3, y + 3, z + 6, Blocks.stone, 0, 3);
		world.setBlock(x + 9, y + 3, z + 6, Blocks.stone, 0, 3);
		world.setBlock(x + 10, y + 3, z + 6, Blocks.leaves, 13, 3);
		world.setBlock(x + 3, y + 3, z + 7, Blocks.stone, 0, 3);
		world.setBlock(x + 9, y + 3, z + 7, Blocks.stonebrick, 1, 3);
		world.setBlock(x + 2, y + 3, z + 8, Blocks.leaves, 5, 3);
		world.setBlock(x + 3, y + 3, z + 8, Blocks.stone, 0, 3);
		world.setBlock(x + 9, y + 3, z + 8, Blocks.stonebrick, 0, 3);
		world.setBlock(x + 3, y + 3, z + 9, Blocks.stone, 0, 3);
		world.setBlock(x + 9, y + 3, z + 9, Blocks.stone, 0, 3);
		world.setBlock(x + 10, y + 3, z + 9, Blocks.leaves, 13, 3);
		world.setBlock(x + 2, y + 3, z + 10, Blocks.leaves, 5, 3);
		world.setBlock(x + 3, y + 3, z + 10, Blocks.stonebrick, 0, 3);
		world.setBlock(x + 4, y + 3, z + 10, Blocks.stonebrick, 1, 3);
		world.setBlock(x + 5, y + 3, z + 10, Blocks.stone, 0, 3);
		world.setBlock(x + 6, y + 3, z + 10, Blocks.stonebrick, 0, 3);
		world.setBlock(x + 7, y + 3, z + 10, Blocks.stonebrick, 0, 3);
		world.setBlock(x + 8, y + 3, z + 10, Blocks.stone, 0, 3);
		world.setBlock(x + 9, y + 3, z + 10, Blocks.stonebrick, 1, 3);
		world.setBlock(x + 10, y + 3, z + 10, Blocks.leaves, 13, 3);
		world.setBlock(x + 11, y + 3, z + 10, Blocks.leaves, 13, 3);
		world.setBlock(x + 0, y + 3, z + 11, Blocks.stonebrick, 0, 3);
		world.setBlock(x + 1, y + 3, z + 11, Blocks.stone, 0, 3);
		world.setBlock(x + 2, y + 3, z + 11, Blocks.stonebrick, 0, 3);
		world.setBlock(x + 3, y + 3, z + 11, Blocks.leaves, 13, 3);
		world.setBlock(x + 4, y + 3, z + 11, Blocks.leaves, 13, 3);
		world.setBlock(x + 5, y + 3, z + 11, Blocks.leaves, 5, 3);
		world.setBlock(x + 6, y + 3, z + 11, Blocks.leaves, 5, 3);
		world.setBlock(x + 8, y + 3, z + 11, Blocks.leaves, 13, 3);
		world.setBlock(x + 9, y + 3, z + 11, Blocks.leaves, 13, 3);
		world.setBlock(x + 10, y + 3, z + 11, Blocks.stonebrick, 0, 3);
		world.setBlock(x + 11, y + 3, z + 11, Blocks.stonebrick, 0, 3);
		world.setBlock(x + 12, y + 3, z + 11, Blocks.stonebrick, 0, 3);
		world.setBlock(x + 2, y + 3, z + 12, Blocks.stone, 0, 3);
		world.setBlock(x + 9, y + 3, z + 12, Blocks.leaves, 5, 3);
		world.setBlock(x + 10, y + 3, z + 12, Blocks.stonebrick, 0, 3);
		world.setBlock(x + 3, y + 4, z + 2, Blocks.stone, 0, 3);
		world.setBlock(x + 4, y + 4, z + 2, Blocks.stonebrick, 1, 3);
		world.setBlock(x + 8, y + 4, z + 2, Blocks.stone, 0, 3);
		world.setBlock(x + 9, y + 4, z + 2, Blocks.stone, 0, 3);
		world.setBlock(x + 2, y + 4, z + 3, Blocks.stonebrick, 0, 3);
		world.setBlock(x + 5, y + 4, z + 3, Blocks.stone, 0, 3);
		world.setBlock(x + 6, y + 4, z + 3, Blocks.stonebrick, 1, 3);
		world.setBlock(x + 7, y + 4, z + 3, Blocks.stone, 0, 3);
		world.setBlock(x + 10, y + 4, z + 3, Blocks.stonebrick, 1, 3);
		world.setBlock(x + 1, y + 4, z + 4, Blocks.leaves, 5, 3);
		world.setBlock(x + 2, y + 4, z + 4, Blocks.stonebrick, 0, 3);
		world.setBlock(x + 10, y + 4, z + 4, Blocks.stonebrick, 1, 3);
		world.setBlock(x + 0, y + 4, z + 5, Blocks.stone, 0, 3);
		world.setBlock(x + 1, y + 4, z + 5, Blocks.stonebrick, 0, 3);
		world.setBlock(x + 2, y + 4, z + 5, Blocks.stone, 0, 3);
		world.setBlock(x + 10, y + 4, z + 5, Blocks.stone, 0, 3);
		world.setBlock(x + 11, y + 4, z + 5, Blocks.stonebrick, 0, 3);
		world.setBlock(x + 12, y + 4, z + 5, Blocks.stone, 0, 3);
		world.setBlock(x + 3, y + 4, z + 6, Blocks.stone, 0, 3);
		world.setBlock(x + 9, y + 4, z + 6, Blocks.stone, 0, 3);
		world.setBlock(x + 10, y + 4, z + 6, Blocks.leaves, 13, 3);
		world.setBlock(x + 3, y + 4, z + 7, Blocks.stone, 0, 3);
		world.setBlock(x + 9, y + 4, z + 7, Blocks.stonebrick, 0, 3);
		world.setBlock(x + 2, y + 4, z + 8, Blocks.leaves, 13, 3);
		world.setBlock(x + 3, y + 4, z + 8, Blocks.stonebrick, 1, 3);
		world.setBlock(x + 9, y + 4, z + 8, Blocks.stonebrick, 1, 3);
		world.setBlock(x + 3, y + 4, z + 9, Blocks.stonebrick, 0, 3);
		world.setBlock(x + 9, y + 4, z + 9, Blocks.stonebrick, 0, 3);
		world.setBlock(x + 10, y + 4, z + 9, Blocks.leaves, 13, 3);
		world.setBlock(x + 2, y + 4, z + 10, Blocks.leaves, 5, 3);
		world.setBlock(x + 3, y + 4, z + 10, Blocks.stonebrick, 0, 3);
		world.setBlock(x + 4, y + 4, z + 10, Blocks.stone, 0, 3);
		world.setBlock(x + 5, y + 4, z + 10, Blocks.stonebrick, 0, 3);
		world.setBlock(x + 6, y + 4, z + 10, Blocks.stonebrick, 1, 3);
		world.setBlock(x + 7, y + 4, z + 10, Blocks.stonebrick, 0, 3);
		world.setBlock(x + 8, y + 4, z + 10, Blocks.stonebrick, 0, 3);
		world.setBlock(x + 9, y + 4, z + 10, Blocks.stonebrick, 1, 3);
		world.setBlock(x + 10, y + 4, z + 10, Blocks.leaves, 13, 3);
		world.setBlock(x + 0, y + 4, z + 11, Blocks.stonebrick, 1, 3);
		world.setBlock(x + 1, y + 4, z + 11, Blocks.stonebrick, 0, 3);
		world.setBlock(x + 2, y + 4, z + 11, Blocks.stonebrick, 0, 3);
		world.setBlock(x + 3, y + 4, z + 11, Blocks.leaves, 13, 3);
		world.setBlock(x + 4, y + 4, z + 11, Blocks.leaves, 5, 3);
		world.setBlock(x + 5, y + 4, z + 11, Blocks.leaves, 5, 3);
		world.setBlock(x + 6, y + 4, z + 11, Blocks.leaves, 5, 3);
		world.setBlock(x + 7, y + 4, z + 11, Blocks.leaves, 5, 3);
		world.setBlock(x + 10, y + 4, z + 11, Blocks.stone, 0, 3);
		world.setBlock(x + 11, y + 4, z + 11, Blocks.stonebrick, 1, 3);
		world.setBlock(x + 12, y + 4, z + 11, Blocks.stonebrick, 1, 3);
		world.setBlock(x + 2, y + 4, z + 12, Blocks.stonebrick, 1, 3);
		world.setBlock(x + 9, y + 4, z + 12, Blocks.leaves, 5, 3);
		world.setBlock(x + 10, y + 4, z + 12, Blocks.stone, 0, 3);
		world.setBlock(x + 3, y + 5, z + 2, Blocks.stone, 0, 3);
		world.setBlock(x + 4, y + 5, z + 2, Blocks.stone, 0, 3);
		world.setBlock(x + 8, y + 5, z + 2, Blocks.stone, 0, 3);
		world.setBlock(x + 9, y + 5, z + 2, Blocks.stone, 0, 3);
		world.setBlock(x + 2, y + 5, z + 3, Blocks.stonebrick, 1, 3);
		world.setBlock(x + 5, y + 5, z + 3, Blocks.stonebrick, 1, 3);
		world.setBlock(x + 6, y + 5, z + 3, Blocks.stone, 0, 3);
		world.setBlock(x + 7, y + 5, z + 3, Blocks.stonebrick, 0, 3);
		world.setBlock(x + 10, y + 5, z + 3, Blocks.stone, 0, 3);
		world.setBlock(x + 1, y + 5, z + 4, Blocks.leaves, 5, 3);
		world.setBlock(x + 2, y + 5, z + 4, Blocks.stonebrick, 0, 3);
		world.setBlock(x + 10, y + 5, z + 4, Blocks.stonebrick, 0, 3);
		world.setBlock(x + 0, y + 5, z + 5, Blocks.stonebrick, 0, 3);
		world.setBlock(x + 1, y + 5, z + 5, Blocks.stonebrick, 0, 3);
		world.setBlock(x + 2, y + 5, z + 5, Blocks.stone, 0, 3);
		world.setBlock(x + 10, y + 5, z + 5, Blocks.stonebrick, 0, 3);
		world.setBlock(x + 11, y + 5, z + 5, Blocks.stone, 0, 3);
		world.setBlock(x + 12, y + 5, z + 5, Blocks.stonebrick, 0, 3);
		world.setBlock(x + 2, y + 5, z + 6, Blocks.leaves, 5, 3);
		world.setBlock(x + 3, y + 5, z + 6, Blocks.stone, 0, 3);
		world.setBlock(x + 9, y + 5, z + 6, Blocks.stone, 0, 3);
		world.setBlock(x + 3, y + 5, z + 7, Blocks.stone, 0, 3);
		world.setBlock(x + 9, y + 5, z + 7, Blocks.stone, 0, 3);
		world.setBlock(x + 3, y + 5, z + 8, Blocks.stone, 0, 3);
		world.setBlock(x + 9, y + 5, z + 8, Blocks.stonebrick, 0, 3);
		world.setBlock(x + 2, y + 5, z + 9, Blocks.leaves, 13, 3);
		world.setBlock(x + 3, y + 5, z + 9, Blocks.stone, 0, 3);
		world.setBlock(x + 9, y + 5, z + 9, Blocks.stonebrick, 0, 3);
		world.setBlock(x + 2, y + 5, z + 10, Blocks.leaves, 5, 3);
		world.setBlock(x + 3, y + 5, z + 10, Blocks.stone, 0, 3);
		world.setBlock(x + 4, y + 5, z + 10, Blocks.stonebrick, 1, 3);
		world.setBlock(x + 5, y + 5, z + 10, Blocks.stone, 0, 3);
		world.setBlock(x + 6, y + 5, z + 10, Blocks.stonebrick, 1, 3);
		world.setBlock(x + 7, y + 5, z + 10, Blocks.stonebrick, 0, 3);
		world.setBlock(x + 8, y + 5, z + 10, Blocks.stonebrick, 0, 3);
		world.setBlock(x + 9, y + 5, z + 10, Blocks.stone, 0, 3);
		world.setBlock(x + 10, y + 5, z + 10, Blocks.leaves, 13, 3);
		world.setBlock(x + 0, y + 5, z + 11, Blocks.stone, 0, 3);
		world.setBlock(x + 1, y + 5, z + 11, Blocks.stonebrick, 0, 3);
		world.setBlock(x + 2, y + 5, z + 11, Blocks.stonebrick, 1, 3);
		world.setBlock(x + 3, y + 5, z + 11, Blocks.leaves, 5, 3);
		world.setBlock(x + 4, y + 5, z + 11, Blocks.leaves, 5, 3);
		world.setBlock(x + 5, y + 5, z + 11, Blocks.leaves, 5, 3);
		world.setBlock(x + 7, y + 5, z + 11, Blocks.leaves, 5, 3);
		world.setBlock(x + 8, y + 5, z + 11, Blocks.leaves, 5, 3);
		world.setBlock(x + 9, y + 5, z + 11, Blocks.leaves, 5, 3);
		world.setBlock(x + 10, y + 5, z + 11, Blocks.stone, 0, 3);
		world.setBlock(x + 11, y + 5, z + 11, Blocks.stonebrick, 0, 3);
		world.setBlock(x + 12, y + 5, z + 11, Blocks.stone, 0, 3);
		world.setBlock(x + 2, y + 5, z + 12, Blocks.stonebrick, 1, 3);
		world.setBlock(x + 9, y + 5, z + 12, Blocks.leaves, 5, 3);
		world.setBlock(x + 10, y + 5, z + 12, Blocks.stonebrick, 1, 3);
		world.setBlock(x + 3, y + 6, z + 2, Blocks.stonebrick, 1, 3);
		world.setBlock(x + 4, y + 6, z + 2, Blocks.stone, 0, 3);
		world.setBlock(x + 8, y + 6, z + 2, Blocks.stone, 0, 3);
		world.setBlock(x + 9, y + 6, z + 2, Blocks.stonebrick, 1, 3);
		world.setBlock(x + 2, y + 6, z + 3, Blocks.stone, 0, 3);
		world.setBlock(x + 5, y + 6, z + 3, Blocks.stone, 0, 3);
		world.setBlock(x + 6, y + 6, z + 3, Blocks.stonebrick, 0, 3);
		world.setBlock(x + 7, y + 6, z + 3, Blocks.stone, 0, 3);
		world.setBlock(x + 10, y + 6, z + 3, Blocks.stonebrick, 0, 3);
		world.setBlock(x + 2, y + 6, z + 4, Blocks.stonebrick, 0, 3);
		world.setBlock(x + 10, y + 6, z + 4, Blocks.stone, 0, 3);
		world.setBlock(x + 0, y + 6, z + 5, Blocks.stonebrick, 0, 3);
		world.setBlock(x + 1, y + 6, z + 5, Blocks.stone, 0, 3);
		world.setBlock(x + 2, y + 6, z + 5, Blocks.stone, 0, 3);
		world.setBlock(x + 10, y + 6, z + 5, Blocks.stone, 0, 3);
		world.setBlock(x + 11, y + 6, z + 5, Blocks.stone, 0, 3);
		world.setBlock(x + 12, y + 6, z + 5, Blocks.stone, 0, 3);
		world.setBlock(x + 3, y + 6, z + 6, Blocks.stonebrick, 1, 3);
		world.setBlock(x + 9, y + 6, z + 6, Blocks.stonebrick, 1, 3);
		world.setBlock(x + 3, y + 6, z + 7, Blocks.stonebrick, 0, 3);
		world.setBlock(x + 9, y + 6, z + 7, Blocks.stonebrick, 0, 3);
		world.setBlock(x + 3, y + 6, z + 8, Blocks.stone, 0, 3);
		world.setBlock(x + 9, y + 6, z + 8, Blocks.stone, 0, 3);
		world.setBlock(x + 2, y + 6, z + 9, Blocks.leaves, 5, 3);
		world.setBlock(x + 3, y + 6, z + 9, Blocks.stonebrick, 0, 3);
		world.setBlock(x + 9, y + 6, z + 9, Blocks.stone, 0, 3);
		world.setBlock(x + 3, y + 6, z + 10, Blocks.stone, 0, 3);
		world.setBlock(x + 4, y + 6, z + 10, Blocks.stone, 0, 3);
		world.setBlock(x + 5, y + 6, z + 10, Blocks.stonebrick, 0, 3);
		world.setBlock(x + 6, y + 6, z + 10, Blocks.stone, 0, 3);
		world.setBlock(x + 7, y + 6, z + 10, Blocks.stonebrick, 0, 3);
		world.setBlock(x + 8, y + 6, z + 10, Blocks.stone, 0, 3);
		world.setBlock(x + 9, y + 6, z + 10, Blocks.stonebrick, 0, 3);
		world.setBlock(x + 10, y + 6, z + 10, Blocks.leaves, 5, 3);
		world.setBlock(x + 0, y + 6, z + 11, Blocks.stonebrick, 0, 3);
		world.setBlock(x + 1, y + 6, z + 11, Blocks.stonebrick, 0, 3);
		world.setBlock(x + 2, y + 6, z + 11, Blocks.stone, 0, 3);
		world.setBlock(x + 3, y + 6, z + 11, Blocks.leaves, 5, 3);
		world.setBlock(x + 4, y + 6, z + 11, Blocks.leaves, 5, 3);
		world.setBlock(x + 10, y + 6, z + 11, Blocks.stonebrick, 1, 3);
		world.setBlock(x + 11, y + 6, z + 11, Blocks.stone, 0, 3);
		world.setBlock(x + 12, y + 6, z + 11, Blocks.stone, 0, 3);
		world.setBlock(x + 2, y + 6, z + 12, Blocks.stone, 0, 3);
		world.setBlock(x + 9, y + 6, z + 12, Blocks.leaves, 5, 3);
		world.setBlock(x + 10, y + 6, z + 12, Blocks.stonebrick, 0, 3);
		world.setBlock(x + 3, y + 7, z + 2, Blocks.stonebrick, 0, 3);
		world.setBlock(x + 4, y + 7, z + 2, Blocks.stone, 0, 3);
		world.setBlock(x + 5, y + 7, z + 2, Blocks.stone_brick_stairs, 5, 3);
		world.setBlock(x + 7, y + 7, z + 2, Blocks.stone_brick_stairs, 4, 3);
		world.setBlock(x + 8, y + 7, z + 2, Blocks.stone, 0, 3);
		world.setBlock(x + 9, y + 7, z + 2, Blocks.stonebrick, 0, 3);
		world.setBlock(x + 2, y + 7, z + 3, Blocks.stone, 0, 3);
		world.setBlock(x + 3, y + 7, z + 3, Blocks.stonebrick, 0, 3);
		world.setBlock(x + 5, y + 7, z + 3, Blocks.stone, 0, 3);
		world.setBlock(x + 6, y + 7, z + 3, Blocks.stone, 0, 3);
		world.setBlock(x + 7, y + 7, z + 3, Blocks.stonebrick, 0, 3);
		world.setBlock(x + 9, y + 7, z + 3, Blocks.stonebrick, 0, 3);
		world.setBlock(x + 10, y + 7, z + 3, Blocks.stone, 0, 3);
		world.setBlock(x + 2, y + 7, z + 4, Blocks.stone, 0, 3);
		world.setBlock(x + 3, y + 7, z + 4, Blocks.stonebrick, 0, 3);
		world.setBlock(x + 9, y + 7, z + 4, Blocks.stonebrick, 0, 3);
		world.setBlock(x + 10, y + 7, z + 4, Blocks.stone, 0, 3);
		world.setBlock(x + 0, y + 7, z + 5, Blocks.stonebrick, 0, 3);
		world.setBlock(x + 1, y + 7, z + 5, Blocks.stone, 0, 3);
		world.setBlock(x + 2, y + 7, z + 5, Blocks.stonebrick, 0, 3);
		world.setBlock(x + 3, y + 7, z + 5, Blocks.stonebrick, 0, 3);
		world.setBlock(x + 9, y + 7, z + 5, Blocks.stonebrick, 0, 3);
		world.setBlock(x + 10, y + 7, z + 5, Blocks.stonebrick, 0, 3);
		world.setBlock(x + 11, y + 7, z + 5, Blocks.stonebrick, 0, 3);
		world.setBlock(x + 12, y + 7, z + 5, Blocks.stonebrick, 0, 3);
		world.setBlock(x + 3, y + 7, z + 6, Blocks.stonebrick, 1, 3);
		world.setBlock(x + 9, y + 7, z + 6, Blocks.stonebrick, 0, 3);
		world.setBlock(x + 3, y + 7, z + 7, Blocks.stonebrick, 0, 3);
		world.setBlock(x + 9, y + 7, z + 7, Blocks.stonebrick, 1, 3);
		world.setBlock(x + 3, y + 7, z + 8, Blocks.stone, 0, 3);
		world.setBlock(x + 9, y + 7, z + 8, Blocks.stonebrick, 0, 3);
		world.setBlock(x + 3, y + 7, z + 9, Blocks.stonebrick, 0, 3);
		world.setBlock(x + 9, y + 7, z + 9, Blocks.stone, 0, 3);
		world.setBlock(x + 3, y + 7, z + 10, Blocks.stonebrick, 1, 3);
		world.setBlock(x + 4, y + 7, z + 10, Blocks.stone, 0, 3);
		world.setBlock(x + 5, y + 7, z + 10, Blocks.stone, 0, 3);
		world.setBlock(x + 6, y + 7, z + 10, Blocks.stone, 0, 3);
		world.setBlock(x + 7, y + 7, z + 10, Blocks.stonebrick, 0, 3);
		world.setBlock(x + 8, y + 7, z + 10, Blocks.stonebrick, 1, 3);
		world.setBlock(x + 9, y + 7, z + 10, Blocks.stonebrick, 0, 3);
		world.setBlock(x + 0, y + 7, z + 11, Blocks.stonebrick, 0, 3);
		world.setBlock(x + 1, y + 7, z + 11, Blocks.stone, 0, 3);
		world.setBlock(x + 2, y + 7, z + 11, Blocks.stonebrick, 1, 3);
		world.setBlock(x + 3, y + 7, z + 11, Blocks.leaves, 5, 3);
		world.setBlock(x + 4, y + 7, z + 11, Blocks.leaves, 5, 3);
		world.setBlock(x + 10, y + 7, z + 11, Blocks.stone, 0, 3);
		world.setBlock(x + 11, y + 7, z + 11, Blocks.stonebrick, 0, 3);
		world.setBlock(x + 12, y + 7, z + 11, Blocks.stonebrick, 0, 3);
		world.setBlock(x + 2, y + 7, z + 12, Blocks.stone, 0, 3);
		world.setBlock(x + 10, y + 7, z + 12, Blocks.stonebrick, 0, 3);
		world.setBlock(x + 3, y + 8, z + 2, Blocks.stone_slab, 0, 3);
		world.setBlock(x + 4, y + 8, z + 2, Blocks.stonebrick, 0, 3);
		world.setBlock(x + 5, y + 8, z + 2, Blocks.stone, 0, 3);
		world.setBlock(x + 6, y + 8, z + 2, Blocks.stonebrick, 0, 3);
		world.setBlock(x + 7, y + 8, z + 2, Blocks.stonebrick, 0, 3);
		world.setBlock(x + 8, y + 8, z + 2, Blocks.stonebrick, 0, 3);
		world.setBlock(x + 9, y + 8, z + 2, Blocks.stone_slab, 0, 3);
		world.setBlock(x + 2, y + 8, z + 3, Blocks.stone_brick_stairs, 2, 3);
		world.setBlock(x + 4, y + 8, z + 3, Blocks.stone_brick_stairs, 0, 3);
		world.setBlock(x + 8, y + 8, z + 3, Blocks.stone_brick_stairs, 1, 3);
		world.setBlock(x + 10, y + 8, z + 3, Blocks.stone_brick_stairs, 2, 3);
		world.setBlock(x + 2, y + 8, z + 4, Blocks.stone, 0, 3);
		world.setBlock(x + 4, y + 8, z + 4, Blocks.stone_brick_stairs, 0, 3);
		world.setBlock(x + 8, y + 8, z + 4, Blocks.stone_brick_stairs, 1, 3);
		world.setBlock(x + 10, y + 8, z + 4, Blocks.stonebrick, 0, 3);
		world.setBlock(x + 0, y + 8, z + 5, Blocks.stone_brick_stairs, 0, 3);
		world.setBlock(x + 1, y + 8, z + 5, Blocks.stonebrick, 0, 3);
		world.setBlock(x + 2, y + 8, z + 5, Blocks.stonebrick, 1, 3);
		world.setBlock(x + 4, y + 8, z + 5, Blocks.stone_brick_stairs, 0, 3);
		world.setBlock(x + 8, y + 8, z + 5, Blocks.stone_brick_stairs, 1, 3);
		world.setBlock(x + 10, y + 8, z + 5, Blocks.stonebrick, 1, 3);
		world.setBlock(x + 11, y + 8, z + 5, Blocks.stone, 0, 3);
		world.setBlock(x + 12, y + 8, z + 5, Blocks.stone_brick_stairs, 1, 3);
		world.setBlock(x + 3, y + 8, z + 6, Blocks.stone, 0, 3);
		world.setBlock(x + 4, y + 8, z + 6, Blocks.stone, 0, 3);
		world.setBlock(x + 8, y + 8, z + 6, Blocks.stonebrick, 1, 3);
		world.setBlock(x + 9, y + 8, z + 6, Blocks.stone, 0, 3);
		world.setBlock(x + 3, y + 8, z + 7, Blocks.stonebrick, 1, 3);
		world.setBlock(x + 9, y + 8, z + 7, Blocks.stonebrick, 1, 3);
		world.setBlock(x + 3, y + 8, z + 8, Blocks.stone, 0, 3);
		world.setBlock(x + 9, y + 8, z + 8, Blocks.stone, 0, 3);
		world.setBlock(x + 3, y + 8, z + 9, Blocks.stone, 0, 3);
		world.setBlock(x + 9, y + 8, z + 9, Blocks.stonebrick, 1, 3);
		world.setBlock(x + 3, y + 8, z + 10, Blocks.stone, 0, 3);
		world.setBlock(x + 4, y + 8, z + 10, Blocks.stonebrick, 0, 3);
		world.setBlock(x + 5, y + 8, z + 10, Blocks.stonebrick, 0, 3);
		world.setBlock(x + 6, y + 8, z + 10, Blocks.stone, 0, 3);
		world.setBlock(x + 7, y + 8, z + 10, Blocks.stone, 0, 3);
		world.setBlock(x + 8, y + 8, z + 10, Blocks.stone, 0, 3);
		world.setBlock(x + 9, y + 8, z + 10, Blocks.stone, 0, 3);
		world.setBlock(x + 0, y + 8, z + 11, Blocks.stone_brick_stairs, 0, 3);
		world.setBlock(x + 1, y + 8, z + 11, Blocks.stone, 0, 3);
		world.setBlock(x + 2, y + 8, z + 11, Blocks.stone, 0, 3);
		world.setBlock(x + 10, y + 8, z + 11, Blocks.stone, 0, 3);
		world.setBlock(x + 11, y + 8, z + 11, Blocks.stonebrick, 0, 3);
		world.setBlock(x + 12, y + 8, z + 11, Blocks.stone_brick_stairs, 1, 3);
		world.setBlock(x + 2, y + 8, z + 12, Blocks.stonebrick, 0, 3);
		world.setBlock(x + 10, y + 8, z + 12, Blocks.stonebrick, 1, 3);
		world.setBlock(x + 4, y + 9, z + 2, Blocks.stone_slab, 0, 3);
		world.setBlock(x + 5, y + 9, z + 2, Blocks.stonebrick, 1, 3);
		world.setBlock(x + 6, y + 9, z + 2, Blocks.stone, 0, 3);
		world.setBlock(x + 7, y + 9, z + 2, Blocks.stone, 0, 3);
		world.setBlock(x + 8, y + 9, z + 2, Blocks.stone_slab, 0, 3);
		world.setBlock(x + 5, y + 9, z + 3, Blocks.stone_brick_stairs, 0, 3);
		world.setBlock(x + 6, y + 9, z + 3, Blocks.stone_slab, 13, 3);
		world.setBlock(x + 7, y + 9, z + 3, Blocks.stone_brick_stairs, 1, 3);
		world.setBlock(x + 2, y + 9, z + 4, Blocks.stonebrick, 1, 3);
		world.setBlock(x + 5, y + 9, z + 4, Blocks.stone_brick_stairs, 0, 3);
		world.setBlock(x + 6, y + 9, z + 4, Blocks.stone_slab, 13, 3);
		world.setBlock(x + 7, y + 9, z + 4, Blocks.stone_brick_stairs, 1, 3);
		world.setBlock(x + 10, y + 9, z + 4, Blocks.stonebrick, 1, 3);
		world.setBlock(x + 1, y + 9, z + 5, Blocks.stonebrick, 0, 3);
		world.setBlock(x + 2, y + 9, z + 5, Blocks.stone, 0, 3);
		world.setBlock(x + 5, y + 9, z + 5, Blocks.stone_brick_stairs, 0, 3);
		world.setBlock(x + 6, y + 9, z + 5, Blocks.stone_slab, 13, 3);
		world.setBlock(x + 7, y + 9, z + 5, Blocks.stone_brick_stairs, 1, 3);
		world.setBlock(x + 10, y + 9, z + 5, Blocks.stone, 0, 3);
		world.setBlock(x + 11, y + 9, z + 5, Blocks.stone, 0, 3);
		world.setBlock(x + 3, y + 9, z + 6, Blocks.stone, 0, 3);
		world.setBlock(x + 4, y + 9, z + 6, Blocks.stonebrick, 0, 3);
		world.setBlock(x + 5, y + 9, z + 6, Blocks.stonebrick, 0, 3);
		world.setBlock(x + 6, y + 9, z + 6, Blocks.stone_slab, 13, 3);
		world.setBlock(x + 7, y + 9, z + 6, Blocks.stonebrick, 0, 3);
		world.setBlock(x + 8, y + 9, z + 6, Blocks.stonebrick, 1, 3);
		world.setBlock(x + 9, y + 9, z + 6, Blocks.stone, 0, 3);
		world.setBlock(x + 3, y + 9, z + 7, Blocks.stone, 0, 3);
		world.setBlock(x + 4, y + 9, z + 7, Blocks.stone_slab, 5, 3);
		world.setBlock(x + 5, y + 9, z + 7, Blocks.stone_slab, 5, 3);
		world.setBlock(x + 6, y + 9, z + 7, Blocks.stone_slab, 5, 3);
		world.setBlock(x + 7, y + 9, z + 7, Blocks.stone_slab, 5, 3);
		world.setBlock(x + 8, y + 9, z + 7, Blocks.stone_slab, 5, 3);
		world.setBlock(x + 9, y + 9, z + 7, Blocks.stone, 0, 3);
		world.setBlock(x + 3, y + 9, z + 8, Blocks.stone, 0, 3);
		world.setBlock(x + 4, y + 9, z + 8, Blocks.stone_slab, 5, 3);
		world.setBlock(x + 5, y + 9, z + 8, Blocks.stone_slab, 5, 3);
		world.setBlock(x + 6, y + 9, z + 8, Blocks.stone_slab, 5, 3);
		world.setBlock(x + 7, y + 9, z + 8, Blocks.stone_slab, 5, 3);
		world.setBlock(x + 8, y + 9, z + 8, Blocks.stone_slab, 5, 3);
		world.setBlock(x + 9, y + 9, z + 8, Blocks.stone, 0, 3);
		world.setBlock(x + 3, y + 9, z + 9, Blocks.stonebrick, 1, 3);
		world.setBlock(x + 4, y + 9, z + 9, Blocks.stone_slab, 5, 3);
		world.setBlock(x + 5, y + 9, z + 9, Blocks.stone_slab, 5, 3);
		world.setBlock(x + 7, y + 9, z + 9, Blocks.stone_slab, 5, 3);
		world.setBlock(x + 8, y + 9, z + 9, Blocks.stone_slab, 5, 3);
		world.setBlock(x + 9, y + 9, z + 9, Blocks.stonebrick, 0, 3);
		world.setBlock(x + 3, y + 9, z + 10, Blocks.stonebrick, 0, 3);
		world.setBlock(x + 4, y + 9, z + 10, Blocks.stonebrick, 1, 3);
		world.setBlock(x + 5, y + 9, z + 10, Blocks.stone, 0, 3);
		world.setBlock(x + 6, y + 9, z + 10, Blocks.stone, 0, 3);
		world.setBlock(x + 7, y + 9, z + 10, Blocks.stonebrick, 0, 3);
		world.setBlock(x + 8, y + 9, z + 10, Blocks.stone, 0, 3);
		world.setBlock(x + 9, y + 9, z + 10, Blocks.stonebrick, 1, 3);
		world.setBlock(x + 1, y + 9, z + 11, Blocks.stonebrick, 1, 3);
		world.setBlock(x + 2, y + 9, z + 11, Blocks.stone, 0, 3);
		world.setBlock(x + 10, y + 9, z + 11, Blocks.stone, 0, 3);
		world.setBlock(x + 11, y + 9, z + 11, Blocks.stone, 0, 3);
		world.setBlock(x + 2, y + 9, z + 12, Blocks.stone, 0, 3);
		world.setBlock(x + 10, y + 9, z + 12, Blocks.stonebrick, 1, 3);
		world.setBlock(x + 5, y + 10, z + 2, Blocks.stone_slab, 0, 3);
		world.setBlock(x + 6, y + 10, z + 2, Blocks.stonebrick, 0, 3);
		world.setBlock(x + 7, y + 10, z + 2, Blocks.stone_slab, 0, 3);
		world.setBlock(x + 6, y + 10, z + 3, Blocks.stone_slab, 5, 3);
		world.setBlock(x + 2, y + 10, z + 4, Blocks.stone, 0, 3);
		world.setBlock(x + 6, y + 10, z + 4, Blocks.stone_slab, 5, 3);
		world.setBlock(x + 10, y + 10, z + 4, Blocks.stonebrick, 1, 3);
		world.setBlock(x + 1, y + 10, z + 5, Blocks.stonebrick, 1, 3);
		world.setBlock(x + 2, y + 10, z + 5, Blocks.stone, 0, 3);
		world.setBlock(x + 6, y + 10, z + 5, Blocks.stone_slab, 5, 3);
		world.setBlock(x + 10, y + 10, z + 5, Blocks.stone, 0, 3);
		world.setBlock(x + 11, y + 10, z + 5, Blocks.stonebrick, 1, 3);
		world.setBlock(x + 3, y + 10, z + 6, Blocks.stone, 0, 3);
		world.setBlock(x + 4, y + 10, z + 6, Blocks.stonebrick, 1, 3);
		world.setBlock(x + 5, y + 10, z + 6, Blocks.stone, 0, 3);
		world.setBlock(x + 6, y + 10, z + 6, Blocks.stonebrick, 0, 3);
		world.setBlock(x + 7, y + 10, z + 6, Blocks.stone, 0, 3);
		world.setBlock(x + 8, y + 10, z + 6, Blocks.stone, 0, 3);
		world.setBlock(x + 9, y + 10, z + 6, Blocks.stonebrick, 1, 3);
		world.setBlock(x + 3, y + 10, z + 7, Blocks.stonebrick, 0, 3);
		world.setBlock(x + 9, y + 10, z + 7, Blocks.stonebrick, 0, 3);
		world.setBlock(x + 3, y + 10, z + 8, Blocks.stained_glass, 13, 3);
		world.setBlock(x + 9, y + 10, z + 8, Blocks.stained_glass, 13, 3);
		world.setBlock(x + 3, y + 10, z + 9, Blocks.stonebrick, 0, 3);
		world.setBlock(x + 9, y + 10, z + 9, Blocks.stone, 0, 3);
		world.setBlock(x + 3, y + 10, z + 10, Blocks.stonebrick, 1, 3);
		world.setBlock(x + 4, y + 10, z + 10, Blocks.stone, 0, 3);
		world.setBlock(x + 5, y + 10, z + 10, Blocks.stonebrick, 0, 3);
		world.setBlock(x + 6, y + 10, z + 10, Blocks.stonebrick, 1, 3);
		world.setBlock(x + 7, y + 10, z + 10, Blocks.stone, 0, 3);
		world.setBlock(x + 8, y + 10, z + 10, Blocks.stone, 0, 3);
		world.setBlock(x + 9, y + 10, z + 10, Blocks.stone, 0, 3);
		world.setBlock(x + 1, y + 10, z + 11, Blocks.stone, 0, 3);
		world.setBlock(x + 2, y + 10, z + 11, Blocks.stonebrick, 1, 3);
		world.setBlock(x + 10, y + 10, z + 11, Blocks.stonebrick, 1, 3);
		world.setBlock(x + 11, y + 10, z + 11, Blocks.stonebrick, 0, 3);
		world.setBlock(x + 2, y + 10, z + 12, Blocks.stone, 0, 3);
		world.setBlock(x + 10, y + 10, z + 12, Blocks.stonebrick, 1, 3);
		world.setBlock(x + 6, y + 11, z + 2, Blocks.stone_slab, 0, 3);
		world.setBlock(x + 2, y + 11, z + 4, Blocks.stone, 0, 3);
		world.setBlock(x + 10, y + 11, z + 4, Blocks.stone, 0, 3);
		world.setBlock(x + 1, y + 11, z + 5, Blocks.stonebrick, 0, 3);
		world.setBlock(x + 2, y + 11, z + 5, Blocks.stone, 0, 3);
		world.setBlock(x + 10, y + 11, z + 5, Blocks.stonebrick, 0, 3);
		world.setBlock(x + 11, y + 11, z + 5, Blocks.stone, 0, 3);
		world.setBlock(x + 3, y + 11, z + 6, Blocks.stone, 0, 3);
		world.setBlock(x + 4, y + 11, z + 6, Blocks.stone, 0, 3);
		world.setBlock(x + 5, y + 11, z + 6, Blocks.stonebrick, 0, 3);
		world.setBlock(x + 6, y + 11, z + 6, Blocks.stonebrick, 1, 3);
		world.setBlock(x + 7, y + 11, z + 6, Blocks.stone, 0, 3);
		world.setBlock(x + 8, y + 11, z + 6, Blocks.stonebrick, 0, 3);
		world.setBlock(x + 9, y + 11, z + 6, Blocks.stone, 0, 3);
		world.setBlock(x + 3, y + 11, z + 7, Blocks.stonebrick, 0, 3);
		world.setBlock(x + 9, y + 11, z + 7, Blocks.stone, 0, 3);
		world.setBlock(x + 3, y + 11, z + 8, Blocks.stained_glass, 13, 3);
		world.setBlock(x + 9, y + 11, z + 8, Blocks.stained_glass, 13, 3);
		world.setBlock(x + 3, y + 11, z + 9, Blocks.stonebrick, 0, 3);
		world.setBlock(x + 9, y + 11, z + 9, Blocks.stone, 0, 3);
		world.setBlock(x + 3, y + 11, z + 10, Blocks.stonebrick, 0, 3);
		world.setBlock(x + 4, y + 11, z + 10, Blocks.stonebrick, 0, 3);
		world.setBlock(x + 5, y + 11, z + 10, Blocks.stone, 0, 3);
		world.setBlock(x + 6, y + 11, z + 10, Blocks.stone, 0, 3);
		world.setBlock(x + 7, y + 11, z + 10, Blocks.stonebrick, 0, 3);
		world.setBlock(x + 8, y + 11, z + 10, Blocks.stone, 0, 3);
		world.setBlock(x + 9, y + 11, z + 10, Blocks.stone, 0, 3);
		world.setBlock(x + 1, y + 11, z + 11, Blocks.stonebrick, 1, 3);
		world.setBlock(x + 2, y + 11, z + 11, Blocks.stone, 0, 3);
		world.setBlock(x + 10, y + 11, z + 11, Blocks.stonebrick, 0, 3);
		world.setBlock(x + 11, y + 11, z + 11, Blocks.stonebrick, 1, 3);
		world.setBlock(x + 2, y + 11, z + 12, Blocks.stone, 0, 3);
		world.setBlock(x + 10, y + 11, z + 12, Blocks.stonebrick, 0, 3);
		world.setBlock(x + 2, y + 12, z + 4, Blocks.stonebrick, 0, 3);
		world.setBlock(x + 10, y + 12, z + 4, Blocks.stonebrick, 0, 3);
		world.setBlock(x + 1, y + 12, z + 5, Blocks.stonebrick, 0, 3);
		world.setBlock(x + 2, y + 12, z + 5, Blocks.stonebrick, 0, 3);
		world.setBlock(x + 10, y + 12, z + 5, Blocks.stone, 0, 3);
		world.setBlock(x + 11, y + 12, z + 5, Blocks.stonebrick, 1, 3);
		world.setBlock(x + 3, y + 12, z + 6, Blocks.stonebrick, 1, 3);
		world.setBlock(x + 4, y + 12, z + 6, Blocks.stonebrick, 0, 3);
		world.setBlock(x + 5, y + 12, z + 6, Blocks.stone, 0, 3);
		world.setBlock(x + 6, y + 12, z + 6, Blocks.stained_glass, 13, 3);
		world.setBlock(x + 7, y + 12, z + 6, Blocks.stonebrick, 0, 3);
		world.setBlock(x + 8, y + 12, z + 6, Blocks.stone, 0, 3);
		world.setBlock(x + 9, y + 12, z + 6, Blocks.stone, 0, 3);
		world.setBlock(x + 3, y + 12, z + 7, Blocks.stone, 0, 3);
		world.setBlock(x + 9, y + 12, z + 7, Blocks.stonebrick, 0, 3);
		world.setBlock(x + 3, y + 12, z + 8, Blocks.stained_glass, 13, 3);
		world.setBlock(x + 9, y + 12, z + 8, Blocks.stained_glass, 13, 3);
		world.setBlock(x + 3, y + 12, z + 9, Blocks.stone, 0, 3);
		world.setBlock(x + 9, y + 12, z + 9, Blocks.stonebrick, 1, 3);
		world.setBlock(x + 3, y + 12, z + 10, Blocks.stonebrick, 1, 3);
		world.setBlock(x + 4, y + 12, z + 10, Blocks.stone, 0, 3);
		world.setBlock(x + 5, y + 12, z + 10, Blocks.stone, 0, 3);
		world.setBlock(x + 6, y + 12, z + 10, Blocks.stonebrick, 0, 3);
		world.setBlock(x + 7, y + 12, z + 10, Blocks.stonebrick, 0, 3);
		world.setBlock(x + 8, y + 12, z + 10, Blocks.stonebrick, 1, 3);
		world.setBlock(x + 9, y + 12, z + 10, Blocks.stone, 0, 3);
		world.setBlock(x + 1, y + 12, z + 11, Blocks.stonebrick, 0, 3);
		world.setBlock(x + 2, y + 12, z + 11, Blocks.stonebrick, 0, 3);
		world.setBlock(x + 10, y + 12, z + 11, Blocks.stone, 0, 3);
		world.setBlock(x + 11, y + 12, z + 11, Blocks.stonebrick, 0, 3);
		world.setBlock(x + 2, y + 12, z + 12, Blocks.stonebrick, 1, 3);
		world.setBlock(x + 10, y + 12, z + 12, Blocks.stone, 0, 3);
		world.setBlock(x + 2, y + 13, z + 4, Blocks.stonebrick, 0, 3);
		world.setBlock(x + 10, y + 13, z + 4, Blocks.stone, 0, 3);
		world.setBlock(x + 1, y + 13, z + 5, Blocks.stone, 0, 3);
		world.setBlock(x + 2, y + 13, z + 5, Blocks.stone, 0, 3);
		world.setBlock(x + 10, y + 13, z + 5, Blocks.stone, 0, 3);
		world.setBlock(x + 11, y + 13, z + 5, Blocks.stonebrick, 0, 3);
		world.setBlock(x + 3, y + 13, z + 6, Blocks.stone, 0, 3);
		world.setBlock(x + 4, y + 13, z + 6, Blocks.stonebrick, 0, 3);
		world.setBlock(x + 5, y + 13, z + 6, Blocks.stone, 0, 3);
		world.setBlock(x + 6, y + 13, z + 6, Blocks.stained_glass, 13, 3);
		world.setBlock(x + 7, y + 13, z + 6, Blocks.stonebrick, 0, 3);
		world.setBlock(x + 8, y + 13, z + 6, Blocks.stone, 0, 3);
		world.setBlock(x + 9, y + 13, z + 6, Blocks.stone, 0, 3);
		world.setBlock(x + 3, y + 13, z + 7, Blocks.stonebrick, 1, 3);
		world.setBlock(x + 9, y + 13, z + 7, Blocks.stone, 0, 3);
		world.setBlock(x + 3, y + 13, z + 8, Blocks.stained_glass, 13, 3);
		world.setBlock(x + 9, y + 13, z + 8, Blocks.stained_glass, 13, 3);
		world.setBlock(x + 3, y + 13, z + 9, Blocks.stone, 0, 3);
		world.setBlock(x + 9, y + 13, z + 9, Blocks.stone, 0, 3);
		world.setBlock(x + 3, y + 13, z + 10, Blocks.stonebrick, 1, 3);
		world.setBlock(x + 4, y + 13, z + 10, Blocks.stonebrick, 1, 3);
		world.setBlock(x + 5, y + 13, z + 10, Blocks.stone, 0, 3);
		world.setBlock(x + 6, y + 13, z + 10, Blocks.stonebrick, 0, 3);
		world.setBlock(x + 7, y + 13, z + 10, Blocks.stonebrick, 0, 3);
		world.setBlock(x + 8, y + 13, z + 10, Blocks.stone, 0, 3);
		world.setBlock(x + 9, y + 13, z + 10, Blocks.stone, 0, 3);
		world.setBlock(x + 1, y + 13, z + 11, Blocks.stonebrick, 0, 3);
		world.setBlock(x + 2, y + 13, z + 11, Blocks.stonebrick, 1, 3);
		world.setBlock(x + 10, y + 13, z + 11, Blocks.stonebrick, 0, 3);
		world.setBlock(x + 11, y + 13, z + 11, Blocks.stone, 0, 3);
		world.setBlock(x + 2, y + 13, z + 12, Blocks.stonebrick, 0, 3);
		world.setBlock(x + 10, y + 13, z + 12, Blocks.stonebrick, 0, 3);
		world.setBlock(x + 2, y + 14, z + 4, Blocks.stonebrick, 0, 3);
		world.setBlock(x + 10, y + 14, z + 4, Blocks.stone, 0, 3);
		world.setBlock(x + 1, y + 14, z + 5, Blocks.stone, 0, 3);
		world.setBlock(x + 2, y + 14, z + 5, Blocks.stonebrick, 0, 3);
		world.setBlock(x + 10, y + 14, z + 5, Blocks.stone, 0, 3);
		world.setBlock(x + 11, y + 14, z + 5, Blocks.stonebrick, 1, 3);
		world.setBlock(x + 3, y + 14, z + 6, Blocks.stone, 0, 3);
		world.setBlock(x + 4, y + 14, z + 6, Blocks.stonebrick, 1, 3);
		world.setBlock(x + 5, y + 14, z + 6, Blocks.stone, 0, 3);
		world.setBlock(x + 6, y + 14, z + 6, Blocks.stained_glass, 13, 3);
		world.setBlock(x + 7, y + 14, z + 6, Blocks.stonebrick, 0, 3);
		world.setBlock(x + 8, y + 14, z + 6, Blocks.stone, 0, 3);
		world.setBlock(x + 9, y + 14, z + 6, Blocks.stonebrick, 0, 3);
		world.setBlock(x + 3, y + 14, z + 7, Blocks.stone, 0, 3);
		world.setBlock(x + 9, y + 14, z + 7, Blocks.stone, 0, 3);
		world.setBlock(x + 3, y + 14, z + 8, Blocks.stained_glass, 13, 3);
		world.setBlock(x + 9, y + 14, z + 8, Blocks.stained_glass, 13, 3);
		world.setBlock(x + 3, y + 14, z + 9, Blocks.stone, 0, 3);
		world.setBlock(x + 9, y + 14, z + 9, Blocks.stonebrick, 0, 3);
		world.setBlock(x + 3, y + 14, z + 10, Blocks.stone, 0, 3);
		world.setBlock(x + 4, y + 14, z + 10, Blocks.stonebrick, 1, 3);
		world.setBlock(x + 5, y + 14, z + 10, Blocks.stone, 0, 3);
		world.setBlock(x + 6, y + 14, z + 10, Blocks.stonebrick, 0, 3);
		world.setBlock(x + 7, y + 14, z + 10, Blocks.stonebrick, 0, 3);
		world.setBlock(x + 8, y + 14, z + 10, Blocks.stonebrick, 1, 3);
		world.setBlock(x + 9, y + 14, z + 10, Blocks.stone, 0, 3);
		world.setBlock(x + 1, y + 14, z + 11, Blocks.stone, 0, 3);
		world.setBlock(x + 2, y + 14, z + 11, Blocks.stone, 0, 3);
		world.setBlock(x + 10, y + 14, z + 11, Blocks.stone, 0, 3);
		world.setBlock(x + 11, y + 14, z + 11, Blocks.stone, 0, 3);
		world.setBlock(x + 2, y + 14, z + 12, Blocks.stonebrick, 1, 3);
		world.setBlock(x + 10, y + 14, z + 12, Blocks.stonebrick, 1, 3);
		world.setBlock(x + 2, y + 15, z + 4, Blocks.stonebrick, 1, 3);
		world.setBlock(x + 10, y + 15, z + 4, Blocks.stonebrick, 1, 3);
		world.setBlock(x + 1, y + 15, z + 5, Blocks.stonebrick, 1, 3);
		world.setBlock(x + 2, y + 15, z + 5, Blocks.stone, 0, 3);
		world.setBlock(x + 10, y + 15, z + 5, Blocks.stonebrick, 0, 3);
		world.setBlock(x + 11, y + 15, z + 5, Blocks.stone, 0, 3);
		world.setBlock(x + 3, y + 15, z + 6, Blocks.stonebrick, 0, 3);
		world.setBlock(x + 4, y + 15, z + 6, Blocks.stone, 0, 3);
		world.setBlock(x + 5, y + 15, z + 6, Blocks.stonebrick, 0, 3);
		world.setBlock(x + 6, y + 15, z + 6, Blocks.stonebrick, 0, 3);
		world.setBlock(x + 7, y + 15, z + 6, Blocks.stone, 0, 3);
		world.setBlock(x + 8, y + 15, z + 6, Blocks.stonebrick, 1, 3);
		world.setBlock(x + 9, y + 15, z + 6, Blocks.stone, 0, 3);
		world.setBlock(x + 3, y + 15, z + 7, Blocks.stone, 0, 3);
		world.setBlock(x + 4, y + 15, z + 7, Blocks.stone_slab, 13, 3);
		world.setBlock(x + 5, y + 15, z + 7, Blocks.stone_slab, 13, 3);
		world.setBlock(x + 6, y + 15, z + 7, Blocks.stone_slab, 13, 3);
		world.setBlock(x + 7, y + 15, z + 7, Blocks.stone_slab, 13, 3);
		world.setBlock(x + 8, y + 15, z + 7, Blocks.stone_slab, 13, 3);
		world.setBlock(x + 9, y + 15, z + 7, Blocks.stonebrick, 1, 3);
		world.setBlock(x + 3, y + 15, z + 8, Blocks.stonebrick, 1, 3);
		world.setBlock(x + 4, y + 15, z + 8, Blocks.stone_slab, 13, 3);
		world.setBlock(x + 5, y + 15, z + 8, Blocks.stone_slab, 13, 3);
		world.setBlock(x + 6, y + 15, z + 8, Blocks.stone_slab, 13, 3);
		world.setBlock(x + 7, y + 15, z + 8, Blocks.stone_slab, 13, 3);
		world.setBlock(x + 8, y + 15, z + 8, Blocks.stone_slab, 13, 3);
		world.setBlock(x + 9, y + 15, z + 8, Blocks.stone, 0, 3);
		world.setBlock(x + 3, y + 15, z + 9, Blocks.stone, 0, 3);
		world.setBlock(x + 4, y + 15, z + 9, Blocks.stone_slab, 13, 3);
		world.setBlock(x + 5, y + 15, z + 9, Blocks.stone_slab, 13, 3);
		world.setBlock(x + 7, y + 15, z + 9, Blocks.stone_slab, 13, 3);
		world.setBlock(x + 8, y + 15, z + 9, Blocks.stone_slab, 13, 3);
		world.setBlock(x + 9, y + 15, z + 9, Blocks.stone, 0, 3);
		world.setBlock(x + 3, y + 15, z + 10, Blocks.stonebrick, 0, 3);
		world.setBlock(x + 4, y + 15, z + 10, Blocks.stone, 0, 3);
		world.setBlock(x + 5, y + 15, z + 10, Blocks.stone, 0, 3);
		world.setBlock(x + 6, y + 15, z + 10, Blocks.stone, 0, 3);
		world.setBlock(x + 7, y + 15, z + 10, Blocks.stonebrick, 0, 3);
		world.setBlock(x + 8, y + 15, z + 10, Blocks.stone, 0, 3);
		world.setBlock(x + 9, y + 15, z + 10, Blocks.stone, 0, 3);
		world.setBlock(x + 1, y + 15, z + 11, Blocks.stone, 0, 3);
		world.setBlock(x + 2, y + 15, z + 11, Blocks.stone, 0, 3);
		world.setBlock(x + 10, y + 15, z + 11, Blocks.stone, 0, 3);
		world.setBlock(x + 11, y + 15, z + 11, Blocks.stonebrick, 1, 3);
		world.setBlock(x + 2, y + 15, z + 12, Blocks.stonebrick, 1, 3);
		world.setBlock(x + 10, y + 15, z + 12, Blocks.stone, 0, 3);
		world.setBlock(x + 2, y + 16, z + 4, Blocks.stone_brick_stairs, 2, 3);
		world.setBlock(x + 10, y + 16, z + 4, Blocks.stone_brick_stairs, 2, 3);
		world.setBlock(x + 1, y + 16, z + 5, Blocks.stone_brick_stairs, 0, 3);
		world.setBlock(x + 2, y + 16, z + 5, Blocks.stonebrick, 1, 3);
		world.setBlock(x + 10, y + 16, z + 5, Blocks.stone, 0, 3);
		world.setBlock(x + 11, y + 16, z + 5, Blocks.stone_brick_stairs, 1, 3);
		world.setBlock(x + 3, y + 16, z + 6, Blocks.stone, 0, 3);
		world.setBlock(x + 4, y + 16, z + 6, Blocks.stone, 0, 3);
		world.setBlock(x + 5, y + 16, z + 6, Blocks.stonebrick, 1, 3);
		world.setBlock(x + 6, y + 16, z + 6, Blocks.stone, 0, 3);
		world.setBlock(x + 7, y + 16, z + 6, Blocks.stone, 0, 3);
		world.setBlock(x + 8, y + 16, z + 6, Blocks.stonebrick, 0, 3);
		world.setBlock(x + 9, y + 16, z + 6, Blocks.stone, 0, 3);
		world.setBlock(x + 3, y + 16, z + 7, Blocks.stonebrick, 0, 3);
		world.setBlock(x + 9, y + 16, z + 7, Blocks.stonebrick, 0, 3);
		world.setBlock(x + 3, y + 16, z + 8, Blocks.stonebrick, 1, 3);
		world.setBlock(x + 9, y + 16, z + 8, Blocks.stone, 0, 3);
		world.setBlock(x + 3, y + 16, z + 9, Blocks.stone, 0, 3);
		world.setBlock(x + 9, y + 16, z + 9, Blocks.stone, 0, 3);
		world.setBlock(x + 3, y + 16, z + 10, Blocks.stonebrick, 0, 3);
		world.setBlock(x + 4, y + 16, z + 10, Blocks.stonebrick, 1, 3);
		world.setBlock(x + 5, y + 16, z + 10, Blocks.stone, 0, 3);
		world.setBlock(x + 6, y + 16, z + 10, Blocks.stone, 0, 3);
		world.setBlock(x + 7, y + 16, z + 10, Blocks.stonebrick, 0, 3);
		world.setBlock(x + 8, y + 16, z + 10, Blocks.stone, 0, 3);
		world.setBlock(x + 9, y + 16, z + 10, Blocks.stonebrick, 1, 3);
		world.setBlock(x + 1, y + 16, z + 11, Blocks.stone_brick_stairs, 0, 3);
		world.setBlock(x + 2, y + 16, z + 11, Blocks.stone, 0, 3);
		world.setBlock(x + 10, y + 16, z + 11, Blocks.stone, 0, 3);
		world.setBlock(x + 11, y + 16, z + 11, Blocks.stone_brick_stairs, 1, 3);
		world.setBlock(x + 2, y + 16, z + 12, Blocks.stone_brick_stairs, 3, 3);
		world.setBlock(x + 10, y + 16, z + 12, Blocks.stone_brick_stairs, 3, 3);
		world.setBlock(x + 2, y + 17, z + 5, Blocks.stone, 0, 3);
		world.setBlock(x + 10, y + 17, z + 5, Blocks.stone, 0, 3);
		world.setBlock(x + 3, y + 17, z + 6, Blocks.stone, 0, 3);
		world.setBlock(x + 4, y + 17, z + 6, Blocks.stonebrick, 0, 3);
		world.setBlock(x + 5, y + 17, z + 6, Blocks.stone, 0, 3);
		world.setBlock(x + 6, y + 17, z + 6, Blocks.stone, 0, 3);
		world.setBlock(x + 7, y + 17, z + 6, Blocks.stone, 0, 3);
		world.setBlock(x + 8, y + 17, z + 6, Blocks.stonebrick, 1, 3);
		world.setBlock(x + 9, y + 17, z + 6, Blocks.stonebrick, 0, 3);
		world.setBlock(x + 3, y + 17, z + 7, Blocks.stone, 0, 3);
		world.setBlock(x + 9, y + 17, z + 7, Blocks.stonebrick, 0, 3);
		world.setBlock(x + 3, y + 17, z + 8, Blocks.stonebrick, 0, 3);
		world.setBlock(x + 9, y + 17, z + 8, Blocks.stonebrick, 1, 3);
		world.setBlock(x + 3, y + 17, z + 9, Blocks.stone, 0, 3);
		world.setBlock(x + 9, y + 17, z + 9, Blocks.stone, 0, 3);
		world.setBlock(x + 3, y + 17, z + 10, Blocks.stonebrick, 1, 3);
		world.setBlock(x + 4, y + 17, z + 10, Blocks.stonebrick, 1, 3);
		world.setBlock(x + 5, y + 17, z + 10, Blocks.stonebrick, 0, 3);
		world.setBlock(x + 6, y + 17, z + 10, Blocks.stone, 0, 3);
		world.setBlock(x + 7, y + 17, z + 10, Blocks.stone, 0, 3);
		world.setBlock(x + 8, y + 17, z + 10, Blocks.stonebrick, 0, 3);
		world.setBlock(x + 9, y + 17, z + 10, Blocks.stonebrick, 0, 3);
		world.setBlock(x + 2, y + 17, z + 11, Blocks.stone, 0, 3);
		world.setBlock(x + 10, y + 17, z + 11, Blocks.stone, 0, 3);
		world.setBlock(x + 2, y + 18, z + 5, Blocks.stone, 0, 3);
		world.setBlock(x + 10, y + 18, z + 5, Blocks.stone, 0, 3);
		world.setBlock(x + 3, y + 18, z + 6, Blocks.stone, 0, 3);
		world.setBlock(x + 4, y + 18, z + 6, Blocks.stonebrick, 0, 3);
		world.setBlock(x + 5, y + 18, z + 6, Blocks.stone, 0, 3);
		world.setBlock(x + 6, y + 18, z + 6, Blocks.stained_glass, 13, 3);
		world.setBlock(x + 7, y + 18, z + 6, Blocks.stone, 0, 3);
		world.setBlock(x + 8, y + 18, z + 6, Blocks.stonebrick, 0, 3);
		world.setBlock(x + 9, y + 18, z + 6, Blocks.stone, 0, 3);
		world.setBlock(x + 3, y + 18, z + 7, Blocks.stone, 0, 3);
		world.setBlock(x + 9, y + 18, z + 7, Blocks.stone, 0, 3);
		world.setBlock(x + 3, y + 18, z + 8, Blocks.stained_glass, 13, 3);
		world.setBlock(x + 9, y + 18, z + 8, Blocks.stained_glass, 13, 3);
		world.setBlock(x + 3, y + 18, z + 9, Blocks.stone, 0, 3);
		world.setBlock(x + 9, y + 18, z + 9, Blocks.stone, 0, 3);
		world.setBlock(x + 3, y + 18, z + 10, Blocks.stone, 0, 3);
		world.setBlock(x + 4, y + 18, z + 10, Blocks.stonebrick, 1, 3);
		world.setBlock(x + 5, y + 18, z + 10, Blocks.stone, 0, 3);
		world.setBlock(x + 6, y + 18, z + 10, Blocks.stonebrick, 1, 3);
		world.setBlock(x + 7, y + 18, z + 10, Blocks.stonebrick, 0, 3);
		world.setBlock(x + 8, y + 18, z + 10, Blocks.stone, 0, 3);
		world.setBlock(x + 9, y + 18, z + 10, Blocks.stonebrick, 1, 3);
		world.setBlock(x + 2, y + 18, z + 11, Blocks.stone, 0, 3);
		world.setBlock(x + 10, y + 18, z + 11, Blocks.stonebrick, 0, 3);
		world.setBlock(x + 2, y + 19, z + 5, Blocks.stone, 0, 3);
		world.setBlock(x + 10, y + 19, z + 5, Blocks.stone, 0, 3);
		world.setBlock(x + 3, y + 19, z + 6, Blocks.stone, 0, 3);
		world.setBlock(x + 4, y + 19, z + 6, Blocks.stone, 0, 3);
		world.setBlock(x + 5, y + 19, z + 6, Blocks.stonebrick, 0, 3);
		world.setBlock(x + 6, y + 19, z + 6, Blocks.stained_glass, 13, 3);
		world.setBlock(x + 7, y + 19, z + 6, Blocks.stonebrick, 1, 3);
		world.setBlock(x + 8, y + 19, z + 6, Blocks.stone, 0, 3);
		world.setBlock(x + 9, y + 19, z + 6, Blocks.stonebrick, 1, 3);
		world.setBlock(x + 3, y + 19, z + 7, Blocks.stonebrick, 1, 3);
		world.setBlock(x + 9, y + 19, z + 7, Blocks.stone, 0, 3);
		world.setBlock(x + 3, y + 19, z + 8, Blocks.stained_glass, 13, 3);
		world.setBlock(x + 9, y + 19, z + 8, Blocks.stained_glass, 13, 3);
		world.setBlock(x + 3, y + 19, z + 9, Blocks.stone, 0, 3);
		world.setBlock(x + 9, y + 19, z + 9, Blocks.stone, 0, 3);
		world.setBlock(x + 3, y + 19, z + 10, Blocks.stonebrick, 1, 3);
		world.setBlock(x + 4, y + 19, z + 10, Blocks.stonebrick, 1, 3);
		world.setBlock(x + 5, y + 19, z + 10, Blocks.stone, 0, 3);
		world.setBlock(x + 6, y + 19, z + 10, Blocks.stonebrick, 0, 3);
		world.setBlock(x + 7, y + 19, z + 10, Blocks.stone, 0, 3);
		world.setBlock(x + 8, y + 19, z + 10, Blocks.stonebrick, 0, 3);
		world.setBlock(x + 9, y + 19, z + 10, Blocks.stonebrick, 0, 3);
		world.setBlock(x + 2, y + 19, z + 11, Blocks.stonebrick, 1, 3);
		world.setBlock(x + 10, y + 19, z + 11, Blocks.stonebrick, 1, 3);
		world.setBlock(x + 2, y + 20, z + 5, Blocks.stonebrick, 1, 3);
		world.setBlock(x + 10, y + 20, z + 5, Blocks.stone, 0, 3);
		world.setBlock(x + 3, y + 20, z + 6, Blocks.stonebrick, 0, 3);
		world.setBlock(x + 4, y + 20, z + 6, Blocks.stone, 0, 3);
		world.setBlock(x + 5, y + 20, z + 6, Blocks.stonebrick, 1, 3);
		world.setBlock(x + 6, y + 20, z + 6, Blocks.stained_glass, 13, 3);
		world.setBlock(x + 7, y + 20, z + 6, Blocks.stone, 0, 3);
		world.setBlock(x + 8, y + 20, z + 6, Blocks.stonebrick, 1, 3);
		world.setBlock(x + 9, y + 20, z + 6, Blocks.stone, 0, 3);
		world.setBlock(x + 3, y + 20, z + 7, Blocks.stonebrick, 1, 3);
		world.setBlock(x + 9, y + 20, z + 7, Blocks.stone, 0, 3);
		world.setBlock(x + 3, y + 20, z + 8, Blocks.stained_glass, 13, 3);
		world.setBlock(x + 9, y + 20, z + 8, Blocks.stained_glass, 13, 3);
		world.setBlock(x + 3, y + 20, z + 9, Blocks.stone, 0, 3);
		world.setBlock(x + 9, y + 20, z + 9, Blocks.stonebrick, 0, 3);
		world.setBlock(x + 3, y + 20, z + 10, Blocks.stone, 0, 3);
		world.setBlock(x + 4, y + 20, z + 10, Blocks.stone, 0, 3);
		world.setBlock(x + 5, y + 20, z + 10, Blocks.stone, 0, 3);
		world.setBlock(x + 6, y + 20, z + 10, Blocks.stonebrick, 0, 3);
		world.setBlock(x + 7, y + 20, z + 10, Blocks.stone, 0, 3);
		world.setBlock(x + 8, y + 20, z + 10, Blocks.stonebrick, 1, 3);
		world.setBlock(x + 9, y + 20, z + 10, Blocks.stone, 0, 3);
		world.setBlock(x + 2, y + 20, z + 11, Blocks.stone, 0, 3);
		world.setBlock(x + 10, y + 20, z + 11, Blocks.stonebrick, 1, 3);
		world.setBlock(x + 2, y + 21, z + 5, Blocks.stonebrick, 0, 3);
		world.setBlock(x + 10, y + 21, z + 5, Blocks.stonebrick, 0, 3);
		world.setBlock(x + 3, y + 21, z + 6, Blocks.stonebrick, 0, 3);
		world.setBlock(x + 4, y + 21, z + 6, Blocks.stone, 0, 3);
		world.setBlock(x + 5, y + 21, z + 6, Blocks.stonebrick, 0, 3);
		world.setBlock(x + 6, y + 21, z + 6, Blocks.stained_glass, 13, 3);
		world.setBlock(x + 7, y + 21, z + 6, Blocks.stone, 0, 3);
		world.setBlock(x + 8, y + 21, z + 6, Blocks.stonebrick, 0, 3);
		world.setBlock(x + 9, y + 21, z + 6, Blocks.stone, 0, 3);
		world.setBlock(x + 3, y + 21, z + 7, Blocks.stone, 0, 3);
		world.setBlock(x + 9, y + 21, z + 7, Blocks.stonebrick, 0, 3);
		world.setBlock(x + 3, y + 21, z + 8, Blocks.stained_glass, 13, 3);
		world.setBlock(x + 9, y + 21, z + 8, Blocks.stained_glass, 13, 3);
		world.setBlock(x + 3, y + 21, z + 9, Blocks.stone, 0, 3);
		world.setBlock(x + 9, y + 21, z + 9, Blocks.stonebrick, 0, 3);
		world.setBlock(x + 3, y + 21, z + 10, Blocks.stonebrick, 1, 3);
		world.setBlock(x + 4, y + 21, z + 10, Blocks.stonebrick, 0, 3);
		world.setBlock(x + 5, y + 21, z + 10, Blocks.stone, 0, 3);
		world.setBlock(x + 6, y + 21, z + 10, Blocks.stonebrick, 1, 3);
		world.setBlock(x + 7, y + 21, z + 10, Blocks.stonebrick, 0, 3);
		world.setBlock(x + 8, y + 21, z + 10, Blocks.stonebrick, 1, 3);
		world.setBlock(x + 9, y + 21, z + 10, Blocks.stone, 0, 3);
		world.setBlock(x + 2, y + 21, z + 11, Blocks.stone, 0, 3);
		world.setBlock(x + 10, y + 21, z + 11, Blocks.stone, 0, 3);
		world.setBlock(x + 2, y + 22, z + 5, Blocks.stonebrick, 1, 3);
		world.setBlock(x + 10, y + 22, z + 5, Blocks.stonebrick, 1, 3);
		world.setBlock(x + 3, y + 22, z + 6, Blocks.stone, 0, 3);
		world.setBlock(x + 4, y + 22, z + 6, Blocks.stone, 0, 3);
		world.setBlock(x + 5, y + 22, z + 6, Blocks.stone, 0, 3);
		world.setBlock(x + 6, y + 22, z + 6, Blocks.stained_glass, 13, 3);
		world.setBlock(x + 7, y + 22, z + 6, Blocks.stonebrick, 0, 3);
		world.setBlock(x + 8, y + 22, z + 6, Blocks.stonebrick, 0, 3);
		world.setBlock(x + 9, y + 22, z + 6, Blocks.stone, 0, 3);
		world.setBlock(x + 3, y + 22, z + 7, Blocks.stone, 0, 3);
		world.setBlock(x + 9, y + 22, z + 7, Blocks.stone, 0, 3);
		world.setBlock(x + 3, y + 22, z + 8, Blocks.stained_glass, 13, 3);
		world.setBlock(x + 9, y + 22, z + 8, Blocks.stained_glass, 13, 3);
		world.setBlock(x + 3, y + 22, z + 9, Blocks.stonebrick, 0, 3);
		world.setBlock(x + 9, y + 22, z + 9, Blocks.stone, 0, 3);
		world.setBlock(x + 3, y + 22, z + 10, Blocks.stone, 0, 3);
		world.setBlock(x + 4, y + 22, z + 10, Blocks.stone, 0, 3);
		world.setBlock(x + 5, y + 22, z + 10, Blocks.stone, 0, 3);
		world.setBlock(x + 6, y + 22, z + 10, Blocks.stonebrick, 0, 3);
		world.setBlock(x + 7, y + 22, z + 10, Blocks.stone, 0, 3);
		world.setBlock(x + 8, y + 22, z + 10, Blocks.stonebrick, 1, 3);
		world.setBlock(x + 9, y + 22, z + 10, Blocks.stonebrick, 1, 3);
		world.setBlock(x + 2, y + 22, z + 11, Blocks.stone, 0, 3);
		world.setBlock(x + 10, y + 22, z + 11, Blocks.stone, 0, 3);
		world.setBlock(x + 2, y + 23, z + 5, Blocks.stone, 0, 3);
		world.setBlock(x + 10, y + 23, z + 5, Blocks.stone, 0, 3);
		world.setBlock(x + 3, y + 23, z + 6, Blocks.stone, 0, 3);
		world.setBlock(x + 4, y + 23, z + 6, Blocks.stone, 0, 3);
		world.setBlock(x + 5, y + 23, z + 6, Blocks.stonebrick, 1, 3);
		world.setBlock(x + 6, y + 23, z + 6, Blocks.stone, 0, 3);
		world.setBlock(x + 7, y + 23, z + 6, Blocks.stonebrick, 1, 3);
		world.setBlock(x + 8, y + 23, z + 6, Blocks.stone, 0, 3);
		world.setBlock(x + 9, y + 23, z + 6, Blocks.stone, 0, 3);
		world.setBlock(x + 3, y + 23, z + 7, Blocks.stonebrick, 0, 3);
		world.setBlock(x + 9, y + 23, z + 7, Blocks.stonebrick, 1, 3);
		world.setBlock(x + 3, y + 23, z + 8, Blocks.stone, 0, 3);
		world.setBlock(x + 9, y + 23, z + 8, Blocks.stone, 0, 3);
		world.setBlock(x + 3, y + 23, z + 9, Blocks.stonebrick, 1, 3);
		world.setBlock(x + 9, y + 23, z + 9, Blocks.stone, 0, 3);
		world.setBlock(x + 3, y + 23, z + 10, Blocks.stone, 0, 3);
		world.setBlock(x + 4, y + 23, z + 10, Blocks.stonebrick, 0, 3);
		world.setBlock(x + 5, y + 23, z + 10, Blocks.stone, 0, 3);
		world.setBlock(x + 6, y + 23, z + 10, Blocks.stonebrick, 0, 3);
		world.setBlock(x + 7, y + 23, z + 10, Blocks.stonebrick, 0, 3);
		world.setBlock(x + 8, y + 23, z + 10, Blocks.stone, 0, 3);
		world.setBlock(x + 9, y + 23, z + 10, Blocks.stone, 0, 3);
		world.setBlock(x + 2, y + 23, z + 11, Blocks.stonebrick, 0, 3);
		world.setBlock(x + 10, y + 23, z + 11, Blocks.stone, 0, 3);
		world.setBlock(x + 2, y + 24, z + 5, Blocks.stone, 0, 3);
		world.setBlock(x + 10, y + 24, z + 5, Blocks.stone, 0, 3);
		world.setBlock(x + 3, y + 24, z + 6, Blocks.stone, 0, 3);
		world.setBlock(x + 4, y + 24, z + 6, Blocks.stonebrick, 0, 3);
		world.setBlock(x + 5, y + 24, z + 6, Blocks.stonebrick, 0, 3);
		world.setBlock(x + 6, y + 24, z + 6, Blocks.stone, 0, 3);
		world.setBlock(x + 7, y + 24, z + 6, Blocks.stone, 0, 3);
		world.setBlock(x + 8, y + 24, z + 6, Blocks.stone, 0, 3);
		world.setBlock(x + 9, y + 24, z + 6, Blocks.stone, 0, 3);
		world.setBlock(x + 3, y + 24, z + 7, Blocks.stonebrick, 0, 3);
		world.setBlock(x + 4, y + 24, z + 7, Blocks.stone_slab, 13, 3);
		world.setBlock(x + 5, y + 24, z + 7, Blocks.stone_slab, 13, 3);
		world.setBlock(x + 6, y + 24, z + 7, Blocks.stone_slab, 13, 3);
		world.setBlock(x + 7, y + 24, z + 7, Blocks.stone_slab, 13, 3);
		world.setBlock(x + 8, y + 24, z + 7, Blocks.stone_slab, 13, 3);
		world.setBlock(x + 9, y + 24, z + 7, Blocks.stone, 0, 3);
		world.setBlock(x + 3, y + 24, z + 8, Blocks.stone, 0, 3);
		world.setBlock(x + 4, y + 24, z + 8, Blocks.stone_slab, 13, 3);
		world.setBlock(x + 5, y + 24, z + 8, Blocks.stone_slab, 13, 3);
		world.setBlock(x + 6, y + 24, z + 8, Blocks.stone_slab, 13, 3);
		world.setBlock(x + 7, y + 24, z + 8, Blocks.stone_slab, 13, 3);
		world.setBlock(x + 8, y + 24, z + 8, Blocks.stone_slab, 13, 3);
		world.setBlock(x + 9, y + 24, z + 8, Blocks.stone, 0, 3);
		world.setBlock(x + 3, y + 24, z + 9, Blocks.stonebrick, 1, 3);
		world.setBlock(x + 4, y + 24, z + 9, Blocks.stone_slab, 13, 3);
		world.setBlock(x + 5, y + 24, z + 9, Blocks.stone_slab, 13, 3);
		world.setBlock(x + 7, y + 24, z + 9, Blocks.stone_slab, 13, 3);
		world.setBlock(x + 8, y + 24, z + 9, Blocks.stone_slab, 13, 3);
		world.setBlock(x + 9, y + 24, z + 9, Blocks.stonebrick, 0, 3);
		world.setBlock(x + 3, y + 24, z + 10, Blocks.stonebrick, 0, 3);
		world.setBlock(x + 4, y + 24, z + 10, Blocks.stone, 0, 3);
		world.setBlock(x + 5, y + 24, z + 10, Blocks.stonebrick, 1, 3);
		world.setBlock(x + 6, y + 24, z + 10, Blocks.stonebrick, 0, 3);
		world.setBlock(x + 7, y + 24, z + 10, Blocks.stone, 0, 3);
		world.setBlock(x + 8, y + 24, z + 10, Blocks.stonebrick, 1, 3);
		world.setBlock(x + 9, y + 24, z + 10, Blocks.stone, 0, 3);
		world.setBlock(x + 2, y + 24, z + 11, Blocks.stone, 0, 3);
		world.setBlock(x + 10, y + 24, z + 11, Blocks.stonebrick, 0, 3);
		world.setBlock(x + 2, y + 25, z + 5, Blocks.stone, 0, 3);
		world.setBlock(x + 10, y + 25, z + 5, Blocks.stone, 0, 3);
		world.setBlock(x + 3, y + 25, z + 6, Blocks.stone_slab, 5, 3);
		world.setBlock(x + 4, y + 25, z + 6, Blocks.stone_slab, 5, 3);
		world.setBlock(x + 5, y + 25, z + 6, Blocks.stone, 0, 3);
		world.setBlock(x + 6, y + 25, z + 6, Blocks.stone_slab, 5, 3);
		world.setBlock(x + 7, y + 25, z + 6, Blocks.stonebrick, 0, 3);
		world.setBlock(x + 8, y + 25, z + 6, Blocks.stone_slab, 5, 3);
		world.setBlock(x + 9, y + 25, z + 6, Blocks.stone_slab, 5, 3);
		world.setBlock(x + 3, y + 25, z + 7, Blocks.stone_slab, 5, 3);
		world.setBlock(x + 9, y + 25, z + 7, Blocks.stone_slab, 5, 3);
		world.setBlock(x + 3, y + 25, z + 8, Blocks.stonebrick, 0, 3);
		world.setBlock(x + 9, y + 25, z + 8, Blocks.stone, 0, 3);
		world.setBlock(x + 3, y + 25, z + 9, Blocks.stone_slab, 5, 3);
		world.setBlock(x + 9, y + 25, z + 9, Blocks.stone_slab, 5, 3);
		world.setBlock(x + 3, y + 25, z + 10, Blocks.stone_slab, 5, 3);
		world.setBlock(x + 4, y + 25, z + 10, Blocks.stone_slab, 5, 3);
		world.setBlock(x + 5, y + 25, z + 10, Blocks.stonebrick, 1, 3);
		world.setBlock(x + 6, y + 25, z + 10, Blocks.stone_slab, 5, 3);
		world.setBlock(x + 7, y + 25, z + 10, Blocks.stone, 0, 3);
		world.setBlock(x + 8, y + 25, z + 10, Blocks.stone_slab, 5, 3);
		world.setBlock(x + 9, y + 25, z + 10, Blocks.stone_slab, 5, 3);
		world.setBlock(x + 2, y + 25, z + 11, Blocks.stonebrick, 1, 3);
		world.setBlock(x + 10, y + 25, z + 11, Blocks.stonebrick, 0, 3);
		world.setBlock(x + 2, y + 26, z + 5, Blocks.stone_slab, 0, 3);
		world.setBlock(x + 10, y + 26, z + 5, Blocks.stone_slab, 0, 3);
		world.setBlock(x + 5, y + 26, z + 6, Blocks.stone_slab, 0, 3);
		world.setBlock(x + 7, y + 26, z + 6, Blocks.stone_slab, 0, 3);
		world.setBlock(x + 3, y + 26, z + 8, Blocks.stone_slab, 0, 3);
		world.setBlock(x + 9, y + 26, z + 8, Blocks.stone_slab, 0, 3);
		world.setBlock(x + 5, y + 26, z + 10, Blocks.stone_slab, 0, 3);
		world.setBlock(x + 7, y + 26, z + 10, Blocks.stone_slab, 0, 3);
		world.setBlock(x + 2, y + 26, z + 11, Blocks.stone_slab, 0, 3);
		world.setBlock(x + 10, y + 26, z + 11, Blocks.stone_slab, 0, 3);
		world.setBlock(x + 6, y + 1, z + 9, Blocks.ladder, 2, 3);
		world.setBlock(x + 6, y + 2, z + 9, Blocks.ladder, 2, 3);
		world.setBlock(x + 6, y + 3, z + 9, Blocks.ladder, 2, 3);
		world.setBlock(x + 6, y + 4, z + 9, Blocks.ladder, 2, 3);
		world.setBlock(x + 6, y + 5, z + 9, Blocks.ladder, 2, 3);
		world.setBlock(x + 5, y + 6, z + 9, Blocks.torch, 4, 3);
		world.setBlock(x + 6, y + 6, z + 9, Blocks.ladder, 2, 3);
		world.setBlock(x + 6, y + 7, z + 9, Blocks.ladder, 2, 3);
		world.setBlock(x + 6, y + 8, z + 9, Blocks.ladder, 2, 3);
		world.setBlock(x + 6, y + 9, z + 9, Blocks.ladder, 2, 3);
		world.setBlock(x + 6, y + 10, z + 9, Blocks.ladder, 2, 3);
		world.setBlock(x + 6, y + 11, z + 9, Blocks.ladder, 2, 3);
		world.setBlock(x + 5, y + 12, z + 9, Blocks.torch, 4, 3);
		world.setBlock(x + 6, y + 12, z + 9, Blocks.ladder, 2, 3);
		world.setBlock(x + 6, y + 13, z + 9, Blocks.ladder, 2, 3);
		world.setBlock(x + 6, y + 14, z + 9, Blocks.ladder, 2, 3);
		world.setBlock(x + 6, y + 15, z + 9, Blocks.ladder, 2, 3);
		world.setBlock(x + 6, y + 16, z + 9, Blocks.ladder, 2, 3);
		world.setBlock(x + 6, y + 17, z + 9, Blocks.ladder, 2, 3);
		world.setBlock(x + 6, y + 18, z + 9, Blocks.ladder, 2, 3);
		world.setBlock(x + 6, y + 19, z + 9, Blocks.ladder, 2, 3);
		world.setBlock(x + 5, y + 20, z + 9, Blocks.torch, 4, 3);
		world.setBlock(x + 6, y + 20, z + 9, Blocks.ladder, 2, 3);
		world.setBlock(x + 6, y + 21, z + 9, Blocks.ladder, 2, 3);
		world.setBlock(x + 6, y + 22, z + 9, Blocks.ladder, 2, 3);
		world.setBlock(x + 6, y + 23, z + 9, Blocks.ladder, 2, 3);
		world.setBlock(x + 6, y + 24, z + 9, Blocks.ladder, 2, 3);
		world.setBlock(x + 4, y + 25, z + 9, Blocks.torch, 5, 3);
		return true;

	}*/

	@Override
	public boolean generate(World worldIn, Random rand, BlockPos position) {
		return false;
	}
}